Workbook

Sheet Dashboard
A1: ISO/IEC 17025:2017 | LABORATORY QMS DASHBOARD (AUDIT READINESS)
A3: Report Date: | G3: =TODAY() -> 46302
A5: EXECUTIVE SUMMARY — KEY PERFORMANCE INDICATORS
A7: TOTAL NCRs LOGGED | C7: OPEN NCRs | E7: NCR CLOSURE RATE | G7: AVG DAYS TO CLOSE NCR | I7: OPEN / IN-PROGRESS CAPA | K7: OVERDUE CAPA
A8: =COUNTA('NCR Register'!A6:A54) -> 29 | C8: =COUNTIFS('NCR Register'!K6:K54,"Open") -> 0 | E8: =IFERROR(COUNTIFS('NCR Register'!K6:K54,"Closed")/COUNTA('NCR Register'!A6:A54),0) -> 0.79310345 | G8: =IFERROR(AVERAGEIFS('NCR Register'!M6:M54,'NCR Register'!K6:K54,"Closed"),0) -> 0 | I8: =COUNTIFS('CAPA Tracker'!J6:J55,"Open")+COUNTIFS('CAPA Tracker'!J6:J55,"In Progress") -> 4 | K8: =COUNTIFS('CAPA Tracker'!J6:J55,"<>Closed",'CAPA Tracker'!J6:J55,"<>",'CAPA Tracker'!I6:I55,"<"&TODAY()) -> 0
A10: Cl. 8.7 | C10: Target: 0 | E10: Target: 100% | G10: Target: <=30 days | I10: Cl. 8.7 | K10: Target: 0
A11: CAPA EFFECTIVENESS VERIFIED | C11: INTERNAL AUDITS COMPLETED (YTD) | E11: OPEN AUDIT FINDINGS | G11: PT/ILC SATISFACTORY RATE | I11: EQUIPMENT CALIBRATION OVERDUE | K11: STAFF COMPETENCY OVERDUE
A12: =IFERROR(COUNTIFS('CAPA Tracker'!M6:M55,"Y")/COUNTIFS('CAPA Tracker'!J6:J55,"Closed"),0) -> 1 | C12: =COUNTIFS('Internal Audits'!I6:I55,"Completed")&" / "&COUNTA('Internal Audits'!A6:A55) -> 7 / 7 | E12: =COUNTIFS('Internal Audits'!K6:K55,"N") -> 0 | G12: =IFERROR(COUNTIFS('PT-ILC'!F6:F55,"Satisfactory")/COUNTIFS('PT-ILC'!F6:F55,"<>Scheduled",'PT-ILC'!F6:F55,"<>"),0) -> 0 | I12: =COUNTIFS(Calibration!I6:I53,"Overdue") -> 0 | K12: =COUNTIFS('Staff Competency'!G6:G80,"Overdue") -> 9
A14: Target: 100% | C14: Cl. 8.8 - Planned | E14: Target: 0 | G14: Cl. 7.7 - Target: 100% | I14: Cl. 6.4 - Target: 0 | K14: Cl. 6.2 - Target: 0
A15: OPEN CUSTOMER COMPLAINTS | C15: AVG DAYS TO CLOSE COMPLAINT | E15: DOCUMENTS OVERDUE REVIEW | G15: DOCUMENTS DUE SOON (90d) | I15: OPEN MGMT REVIEW ACTIONS | K15: AUDIT READINESS SCORE
A16: =COUNTIFS('Customer Feedback'!H6:H55,"Open") -> 1 | C16: =IFERROR(AVERAGEIFS('Customer Feedback'!J6:J55,'Customer Feedback'!H6:H55,"Closed"),0) -> 12 | E16: =COUNTIFS('Document Control'!H6:H55,"Overdue") -> 7 | G16: =COUNTIFS('Document Control'!H6:H55,"Due Soon") -> 0 | I16: =COUNTIFS('Management Review'!G6:G55,"Open") -> 2 | K16: =ROUND(100*AVERAGE(IFERROR(COUNTIFS('NCR Register'!K6:K54,"Closed")/COUNTA('NCR Register'!A6:A54),1),IF(COUNTIFS('CAPA Tracker'!J6:J55,"<>Closed",'CAPA Tracker'!J6:J55,"<>",'CAPA Tracker'!I6:I55,"<"&TODAY())=0,1,0),IF(COUNTIFS(Calibration!I6:I53,"Overdue")=0,1,0),IF(COUNTIFS('Staff Competency'!G6:G80,"Overdue")=0,1,0),IFERROR(COUNTIFS('PT-ILC'!F6:F55,"Satisfactory")/COUNTIFS('PT-ILC'!F6:F55,"<>Scheduled",'PT-ILC'!F6:F55,"<>"),1),IF(COUNTIFS('Document Control'!H6:H55,"Overdue")=0,1,0)),0) -> 63
A18: Cl. 7.9 - Target: 0 | C18: Target: <=15 days | E18: Cl. 8.3 - Target: 0 | I18: Cl. 8.9 - Target: 0 | K18: Composite - Target: 100%
A20: TREND & DISTRIBUTION ANALYSIS
A53: Data source tabs: NCR Register | CAPA Tracker | Internal Audits | PT-ILC | Calibration | Staff Competency | Customer Feedback | Document Control | Management Review. All KPIs recalculate automatically as log sheets are updated (F9 / auto-calc on open).

Sheet NCR Register
A1: ISO/IEC 17025:2017 QMS DASHBOARD | NCR REGISTER
A2: Blue-font cells are example/input rows — overwrite or extend with your own records. Do not delete the header row or column structure (dashboard formulas depend on it).
A3: Legend: Blue text = example data to edit | Black text = formula (auto-calculated) — do not overwrite.
A5: NCR No | B5: Date Raised | C5: Source | D5: ISO 17025 Clause Ref | E5: Description of Nonconformity | F5: Severity | G5: Root Cause | H5: Corrective Action | I5: Responsible | J5: Target Closure Date | K5: Status | L5: Actual Closure Date | M5: Days to Close | N5: Verified By | O5: Effectiveness Check Date
A6: NC01 09/2025 | B6: 05/09/2025 | C6: Material Processing | D6: ISO 17034, Clause 7.5. | E6: CRM's of two different qualities were packaged and labelled as one sample CRM 006 and PT A Aug 2025. | F6: Major | G6: Inadequate planning for future in that at the time of packaging, stickers were unavailable. Cross contamination due to incorrect storage/handling | H6: Isolate the affected CRM batches and remove them from storage. | I6: Tshepo Maponya | J6: 06/09/2025 | K6: Closed | L6: 06/09/2025 | M6: 0 | N6: Laboratory Supervisor | O6: Effective
A7: NC02 09/2025 | B7: 15/09/2025 | C7: PTS Reports | D7: SANAS R80-06 Clause 7.3. | E7: Reference values & their establishment omitted within all PT reports (1-6). | F7: Minor | G7: Oversight when doing the checklist requirements of a PT report (see report for details). | H7: Add a section for CRM characterisation and their establishment on the PT final report. | I7: Operation Manager | J7: 15/09/2025 | K7: Closed | L7: 15/09/2025 | M7: 0 | N7: Laboratory Manager | O7: Effective
A8: NC03 09/2025 | B8: 19/09/2025 | C8: QC Charts | D8: ISO 17025 Clause 7.7 | E8: There are 11 points on one side of the IM control chart(02/06-18/09). The bias was not investigated. | F8: Major | G8: The primary root cause was negligence as well as lack of understanding of significance of job, | H8: A new control was opened since the previous one was approaching an end/finishing. The remaining coal in the near empty pulp was heavily oxidised due to usage and most of the moisture had escaped. | I8: Sifiso Nyambi | J8: 20/09/2025 | K8: Closed | L8: 20/09/2025 | M8: 0 | N8: Laboratory Manager | O8: Effective
A9: NC03/2025 T | B9: 05/01/2026 | C9: Assessment and monitoring of stability | D9: ISO 17034, Clause 7.11. | E9: Stability monitoring results for CRM004 and CRM 005 (July-Dec 2025) were incorrectly assigned due to swapping of CRM bottles during storage | F9: Major | G9: * CRM stickers not available at the time of packaging. * No secondary/temporary labelling system defined for use during stickers shortage *Packaging procedure allows packaging to proceed when CRM stickers | H9: CRM preparation and packaging procedure was revised to mandate immediate individual bottle labelling during packaging and to prohibit CRM units storage/testing unless permanent identification labels are available amd applied. A formal hold or quarantine process including approved temp identification was introduced for such situations where labels are unavailable. | I9: Sifiso Nyambi | J9: 06/01/2026 | K9: Closed | L9: 06/01/2026 | M9: 0 | N9: Laboratory Manager | O9: Effective
A10: NC04/2026 T | B10: 15/01/2026 | C10: Technical Records | D10: ISO 17025 7.5.1 | E10: No records for 4.75mm crusher efficiency | F10: Major | G10: The procedure lacked explicit instruction on the crusher effeiciency of 4.75mm. Thus, efficiency was done unofficially. | H10: Update the ASIW001 document to include when to do the efficiency of the crusher in question. | I10: N. Msibi | J10: 16/01/2026 | K10: Closed | L10: 16/01/2026 | M10: 0 | N10: Laboratory Manager | O10: Effective
A11: NC05/2026 | B11: 15/01/2026 | C11: Technical Records | D11: ISO 17025 7.5.1 | E11: No records for in-house maintenance of equipment | F11: Minor | G11: Initially, the lab did not see the need to have an in-house given that service providers leave job cards after major maintenances. | H11: Purchase an in-house maintenance book | I11: N. Msibi | J11: 28/01/2026 | K11: Closed | L11: 28/01/2026 | M11: 0 | N11: Laboratory Manager | O11: Effective
A12: NC06/2026 T | B12: 05/02/2026 | C12: Structural Requirements | D12: ISO 17025(SANAS F48 cl 5.3) | E12: CAB claimed conformity/accreditation to ISO/IEC 17025 even though it is still going through the accreditation process | F12: Major | G12: The lab did not intend to claim conformity/accreditation. CAB only meant that the QMS is designed based on the structure of ISO 17025. | H12: Revise the document to make it clear about the position of the lab's non accredited status. | I12: Sifiso Nyambi | J12: 10/02/2026 | K12: Closed | L12: 10/02/2026 | M12: 0 | N12: Laboratory Manager | O12: Effective
A13: NC07/2026 T | B13: 02/09/2026 | C13: Structural Requirements | D13: ISO 17025 (SANAS 5.4 F48-07) | E13: The requirements of the standard, customer regulatory authorities and organization providing regulation was not addressed/documented in the QMS of the CAB | F13: Major | G13: The QMS was still being developed therefore the document that states the requirement of standards, customers, regulatory authorities was not drafted leading to an incomplete system documentation | H13: The drafting of the requirements of standards, customer, reg auth etc (ASMF5.4) was done | I13: Sifiso Nyambi | J13: 10/02/2026 | K13: Closed | L13: 10/02/2026 | M13: 0 | N13: Laboratory Manager | O13: Effective
A14: NC08/2026 T | B14: 04/02/2026 | C14: Externally Provided Products and Services | D14: ISO 17025 (SANAS 6.6.2 F48-07) | E14: The subcontractor/coutractor register doesn't list any supplier/service provider. Another point that was not addressed: how does the lifted evaluation criteria for supplies or services help in assessing their performance. | F14: Major | G14: Oversight and human error were the root cause through the use of cause tool | H14: The updated list for evaulation was created | I14: Sifiso Nyambi | J14: 06/02/2026 | K14: Closed | L14: 06/02/2026 | M14: 0 | N14: Laboratory Manager | O14: Effective
A15: NC09/2026 T | B15: 02/09/2026 | C15: Customer Complaints | D15: ISO 17025 (SANAS F48 Cl7.9.2) & 7.9.7 | E15: Cab did not outline how it intends to make the complaint handling process avaliable to interested parties and how it plans to issue communication of the final outcome of logged complaints | F15: Minor | G15: The issue was caused by oversight and incomplete system documentation. Although the complaint and appeal handling information was avaliable on the company website, it was not fully captured in the formal complaint and appeal procedure document | H15: The complaint and appeal procedure document (ASMF 7.18B) was updated to include the information already published on the website | I15: Sifiso Nyambi | J15: 09/02/2026 | K15: Closed | L15: 09/02/2026 | M15: 0 | N15: Laboratory Manager | O15: Effective
A16: NC10/2026 T | B16: 02/09/2026 | C16: Non Conforming Work | D16: ISO 17025 (SANAS F48-07 Cl7.10) | E16: The responsibility for authorising the resumption of work not clearly defined in 7.17 document | F16: Major | G16: Due to incomplete system documentation, nowhere in the documented system was it clearly stated as to who gives authority for resumption of work | H16: The drafting or updating of the document (ASMF7.17) clearly stating that the operations/ lab manager authorizes resumption of work | I16: Sifiso Nyambi | J16: 10/02/2026 | K16: Closed | L16: 10/02/2026 | M16: 0 | N16: Laboratory Manager | O16: Effective
A17: NC11/2026 | B17: 10/02/2026 | C17: Technical Records | D17: ISO 17025 7.2.1.2 | E17: The sampled procedure for the determination of inherent moisture AS0041W has no date (effective and next review date) | F17: Major | G17: This matter was an oversight and as a result, there was no effective and next review date for the sampled procedure for determination of inherent moisture AS0041W | H17: The document AS0041W was updated with the effective date and next review date | I17: Tshepo Maponya | J17: 11/02/2026 | K17: Closed | L17: 11/02/2026 | M17: 0 | N17: Laboratory Supervisor | O17: Effective
... A28: NC26/2026 | B28: 27/08/2026 | C28: Non Conforming Work and LIMS | D28: ISO 17025 Cl 7.10 and 7.11 | E28: Formatting error in the automated LIMS export template caused TM figures to be truncated to one decimal place and incorrectly rendered from 2 stage primary database entries. | F28: major | G28: Inadequate validation of macros template | H28: Decommission the faulty export sheet, Update the macroscript to pull the float values of TM directly from the primary SQL/LIMS toable using proper rounding functions and Lock the macroscript and sheet structure to prevent unauthorised formula adjustments. | I28: Sifiso Nyambi | J28: 28/08/2026 | K28: Closed | L28: 28/08/2026 | M28: 0 | N28: Operations Manager | O28: Effective (to be properly verified using next bias test)
A29: NC028/2026 | B29: 02/09/2026 | C29: Evaluation and Performance and PT Reports | D29: ISO 17043 Cl 7.4.2 and 7.4.3 | E29: The publised PT reports contain conflicting information regarding z-score investigating thresholds and ambigous boundary rules. | F29: Major | G29: Inconsistent harmonisation b/w different reporting templates and historical lack of an explicit procedural rule governing absolute value distance, range boundaries, and strict boundary limits for questionable vs satisfactory ratings. | H29: Fix the conflicting statement regarding the z-scores and send a re-issue to VAS. | I29: Sifiso Nyambi | J29: 03/09/2026 | L29: 03/09/2026 | M29: 0 | N29: PT coordinator
A30: NC030/2026 | B30: 17/06/2026 | C30: Corrective Action | D30: ISO 17025 8.7 | E30: During the external audit, a non-conformance was identified regarding auditor competency. The individual designated by management to execute the internal audit(Managing Director) lacks formal ISO/IEC 17025 internal auditor training, certification, or verifiable auditor experience. Currently, the company does not posses any internal personnel with the necessary qualifications to legally perform quality or technical internal audits. This was flagged during external assessment as an invalid control that threatens the integrity and independence of the QMS | F30: Major | I30: Tshepo Maponya
A31: NC31/2026 | B31: 14/09/2026 | C31: Internal Audit | D31: ISO 17025 8.8 | E31: The internal audit planned for August 2026, covering personnel competence, training and impartiality was not conducted as scheduled. No valid documented reason or evidence of approved scheduling was provided for the missed audit. | F31: Major | I31: Sifiso Nyambi
A32: NC32/2026 | B32: 14/09/2026 | C32: Externally Provided Products and Services | D32: ISO 17025 6.6 | E32: Document ASMF 5.3 requires externally provided services, including outsourced analysis, to be evaluated and approved prior to use. However, it was found that the Total Sulphur for AES report Nos. 1 & 2 was outsourced to a service provider that had not been evaluated and approved prior to use, contrary to the established procedure. | F32: Major | I32: Sifiso Nyambi
A33: NC33/2026 | B33: 05/10/2026 | C33: Personnel and Management Review | D33: ISO 17025 cl 6.2.2 and 8.9.3 | E33: During the MRM (may 2026), it was documentedthat the safety medical certificates for operations and lab manager had expired in April 2026. Action was assigned to renew the medicals by July 2026 during the execution of Vryheid safety file. As of October 2026, these medicals remain undone, thus leaving key lab personnel operating 6 months past their medical epiratio date and 3 months past the MRM target completion date without valid health clearance or documented risk assessment. | F33: Major | I33: Sifiso Nyambi
A34: NC34/2026 | B34: 05/10/2026 | C34: Management Review | D34: ISO 17025 cl 8.9.3 | E34: During the MRM (may 2026), personnel raised grievances regarding excessive workload and resource constraints. Action item 9 was recorded in the table requiring operations manager to setup internal feedback form/system by July 2026. As of October 2026, the grievance form/system has not been developed or implemented, exceeding agreed target date by 3 months. | F34: Major | I34: Sifiso Nyambi

Sheet CAPA Tracker
A1: ISO/IEC 17025:2017 QMS DASHBOARD | CAPA TRACKER
A2: Blue-font cells are example/input rows — overwrite or extend with your own records. Do not delete the header row or column structure (dashboard formulas depend on it).
A3: Legend: Blue text = example data to edit | Black text = formula (auto-calculated) — do not overwrite.
A5: CAPA No | B5: Linked NCR/ Source Ref | C5: Date Raised | D5: Type | E5: Description | F5: Root Cause Method Used | G5: Action Plan | H5: Responsible | I5: Target Date | J5: Status | K5: Closure Date | L5: Days Open | M5: Effectiveness Verified (Y/N) | N5: Effectiveness Review Date | O5: Comments
A6: CAPA-2026-01 | B6: NCR-2026-01 | C6: 2026-01-15 | D6: Corrective | E6: Eliminate recurrence of missed verification sign-off | F6: 5 Why | G6: Digitised checksheet with mandatory verifier field; SOP QP-07 revised | H6: Lab Supervisor | I6: 2026-02-15 | J6: Closed | K6: 2026-02-10 | L6: =IF(K6="",TODAY()-C6,K6-C6) -> 26 | M6: Y | N6: 2026-05-10 | O6: Effective - zero recurrence in 90-day review
A7: CAPA-2026-02 | B7: NCR-2026-02 | C7: 2026-01-23 | D7: Corrective | E7: Prevent load cell drift going undetected | F7: Fishbone | G7: Reduced calibration interval; added interim daily check with reference load | H7: QC Engineer | I7: 2026-02-23 | J7: Closed | K7: 2026-02-18 | L7: =IF(K7="",TODAY()-C7,K7-C7) -> 26 | M7: Y | N7: 2026-05-18 | O7: Effective
A8: CAPA-2026-03 | B8: NCR-2026-03 | C8: 2026-02-04 | D8: Corrective | E8: Correct technique variance on Atterberg Limits | F8: 5 Why | G8: Refresher training + witnessed assessment for all Geotech staff on D4318 | H8: Geotech Lead | I8: 2026-03-06 | J8: Closed | K8: 2026-02-28 | L8: =IF(K8="",TODAY()-C8,K8-C8) -> 24 | M8: Y | N8: 2026-05-28 | O8: Effective - satisfactory PT re-run
A9: CAPA-2026-04 | B9: NCR-2026-04 | C9: 2026-02-12 | D9: Corrective | E9: Eliminate manual transcription errors | F9: Process Mapping | G9: Automated data transfer from sieve balance to report template | H9: IT/QA Coordinator | I9: 2026-03-31 | J9: Closed | K9: 2026-03-25 | L9: =IF(K9="",TODAY()-C9,K9-C9) -> 41 | M9: Y | N9: 2026-06-25 | O9: Effective
A10: CAPA-2026-05 | B10: - | C10: 2026-03-10 | D10: Preventive | E10: Reduce single point of failure risk across critical test methods | F10: Risk Assessment (Cl. 8.5) | G10: Cross-training plan for 3 critical methods across 2 backup staff each | H10: Technical Manager | I10: 2026-06-30 | J10: In Progress | L10: =IF(K10="",TODAY()-C10,K10-C10) -> 211 | M10: N
A11: CAPA-2026-06 | B11: NCR-2026-06 | C11: 2026-03-19 | D11: Corrective | E11: Ensure environmental data always captured | F11: 5 Why | G11: Checksheet field made mandatory in LIMS; validation rule added | H11: Soils Section Head | I11: 2026-04-19 | J11: In Progress | L11: =IF(K11="",TODAY()-C11,K11-C11) -> 202 | M11: N
A12: CAPA-2026-07 | B12: NCR-2026-07 | C12: 2026-04-06 | D12: Corrective | E12: Prevent worn sieve mesh going undetected | F12: Fishbone | G12: Interim verification frequency increased; sieve wear log introduced | H12: QC Engineer | I12: 2026-05-06 | J12: Open | L12: =IF(K12="",TODAY()-C12,K12-C12) -> 184 | M12: N
A13: CAPA-2026-08 | B13: NCR-2026-08 | C13: 2026-04-21 | D13: Preventive | E13: Close competency gap on bitumen ductility method | F13: Risk Assessment | G13: Second technician nominated; training booked with external provider | H13: Technical Manager | I13: 2026-07-21 | J13: Open | L13: =IF(K13="",TODAY()-C13,K13-C13) -> 169 | M13: N

Sheet Internal Audits
A1: ISO/IEC 17025:2017 QMS DASHBOARD | INTERNAL AUDITS
A2: Blue-font cells are example/input rows — overwrite or extend with your own records. Do not delete the header row or column structure (dashboard formulas depend on it).
A3: Legend: Blue text = example data to edit | Black text = formula (auto-calculated) — do not overwrite.
A5: Audit No | B5: Audit Date | C5: Area/Clause Audited | D5: Auditor | E5: Major NCs | F5: Minor NCs | G5: OFIs | H5: Total Findings | I5: Status | J5: Report Issue Date | K5: All Findings Closed (Y/N) | L5: Next Audit Due
A6: IA-2026-01 | B6: 46043 | C6: Management requirements of ISO 17025 | D6: S. Nyambi & TMJ Maponya | E6: 0 | F6: 0 | G6: 0 | H6: 0 | I6: Completed | J6: 46043 | K6: N/A | L6: 2027
A7: IA-2026-01 | B7: 46049 | C7: Technical requirements & VC for PTS | D7: S. Nyambi & TMJ Maponya | E7: 0 | F7: 0 | G7: 0 | H7: 0 | I7: Completed | J7: 46049 | K7: N/A | L7: 2027
A8: IA-2026-05 N1 | B8: 46154 | C8: Managament requirements (Cl 4 and 5) | D8: N Msibi | E8: 0 | F8: 0 | G8: 0 | I8: Completed | J8: 46154 | K8: N/A | L8: 2027
A9: IA-2026-05 N2 | B9: 46156 | C9: Managament requirements (Cl 8) | D9: N Msibi | E9: 0 | F9: 0 | G9: 0 | H9: 0 | I9: Completed | J9: 46156 | K9: N/A | L9: 2027
A10: IA-2026-07 | B10: 46227 | C10: Managament requirements (Cl 8.1-8.3) | D10: N Msibi | E10: 0 | F10: 0 | G10: 0 | H10: 0 | I10: Completed | J10: 46227 | K10: N/A | L10: 2027
A11: IA-2026-09 N1 | B11: 46287 | C11: ISO 17025 Clause 6,2 ;4.1 | D11: N Msibi | E11: 0 | F11: 0 | G11: 0 | H11: 0 | I11: Completed | J11: 46287 | K11: N/A | L11: 2027
A12: IA-2026 09 N2 | B12: 46288 | C12: ISO 17025 Clause 6,3 - 6.4 | D12: N Msibi | E12: 0 | F12: 0 | G12: 0 | H12: 0 | I12: Completed | J12: 46288 | K12: N/A | L12: 2027

Sheet PT-ILC
A1: ISO/IEC 17025:2017 QMS DASHBOARD | PT-ILC
A2: Blue-font cells are example/input rows — overwrite or extend with your own records. Do not delete the header row or column structure (dashboard formulas depend on it).
A3: Legend: Blue text = example data to edit | Black text = formula (auto-calculated) — do not overwrite.
A5: PT/ILC No | B5: Scheme Provider | C5: Test Parameter / Method | D5: Participation Date | E5: Result (Z-score/En) | F5: Performance | G5: Corrective Action Required (Y/N) | H5: CAPA Ref | I5: Status | J5: Next Participation Due
I6: Closed
I7: Closed
I8: Closed
I9: In Progress
I10: Closed
I11: Closed
I12: Scheduled

Sheet Calibration
A1: ISO/IEC 17025:2017 QMS DASHBOARD | CALIBRATION
A2: Blue-font cells are example/input rows — overwrite or extend with your own records. Do not delete the header row or column structure (dashboard formulas depend on it).
A3: Legend: Blue text = example data to edit | Black text = formula (auto-calculated) — do not overwrite.
A5: Equipment ID | B5: Equipment / Instrument Name | C5: Location / Section | D5: Accredited Provider (Y/N) | E5: Last Calibration Date | F5: Interval (Months) | G5: Due Date | H5: Certificate No | I5: Status | J5: Days to Due
A6: AS025PA | B6: Platform Scale | C6: Prep | D6: Y | E6: 27-02-2026 | F6: 12 | G6: 46477 | H6: AZU F1.2 | I6: =IF(G6<TODAY(),"Overdue",IF(G6<TODAY()+30,"Due Soon","Valid")) -> Valid | J6: =G6-TODAY() -> 175
A7: AS00A31 | B7: Top pan balance | C7: Prep | D7: Y | E7: 27-02-2026 | F7: 12 | G7: 46477 | H7: AZU T1.2 | I7: =IF(G7<TODAY(),"Overdue",IF(G7<TODAY()+30,"Due Soon","Valid")) -> Valid | J7: =G7-TODAY() -> 175
A8: AS2156 | B8: Analytical balance | C8: Analysis Room | D8: Y | E8: 27-02-2026 | F8: 12 | G8: 46477 | H8: AZU A1.2 | I8: =IF(G8<TODAY(),"Overdue",IF(G8<TODAY()+30,"Due Soon","Valid")) -> Valid | J8: =G8-TODAY() -> 175
A9: AS0096D | B9: Hygrometer | C9: Analysis Room | D9: Y | E9: 19-03-2026 | F9: 12 | G9: 46477 | H9: AZUS TH2.1 | I9: =IF(G9<TODAY(),"Overdue",IF(G9<TODAY()+30,"Due Soon","Valid")) -> Valid | J9: =G9-TODAY() -> 175
A10: AS02217 | B10: Ash Furnace | C10: Furnace room | D10: Y | E10: 27-02-2026 | F10: 12 | G10: 46477 | H10: AZU AF1.2 | I10: =IF(G10<TODAY(),"Overdue",IF(G10<TODAY()+30,"Due Soon","Valid")) -> Valid | J10: =G10-TODAY() -> 175
A11: AS01338 | B11: Volatile Furnace | C11: Furnace room | D11: Y | E11: 27-02-2026 | F11: 12 | G11: 46477 | H11: AZU VF1.2 | I11: =IF(G11<TODAY(),"Overdue",IF(G11<TODAY()+30,"Due Soon","Valid")) -> Valid | J11: =G11-TODAY() -> 175
A12: AS3800 | B12: IM drying oven | C12: Analysis room | D12: Y | E12: 27-02-2026 | F12: 12 | G12: 46477 | H12: AZU MO1.2 | I12: =IF(G12<TODAY(),"Overdue",IF(G12<TODAY()+30,"Due Soon","Valid")) -> Valid | J12: =G12-TODAY() -> 175
A13: AS00110 | B13: Mass pieces | C13: Analysis room | D13: Y | E13: 17-03-2025 | F13: 12 | G13: 46477 | H13: OB WS1.1R | I13: =IF(G13<TODAY(),"Overdue",IF(G13<TODAY()+30,"Due Soon","Valid")) -> Valid | J13: =G13-TODAY() -> 175
A14: AS8284 | B14: Probe and thermometer | C14: Manager’s office | D14: Y | E14: 03-2026 | F14: 12 | G14: 46477 | H14: CAL/2026/0102 | I14: =IF(G14<TODAY(),"Overdue",IF(G14<TODAY()+30,"Due Soon","Valid")) -> Valid | J14: =G14-TODAY() -> 175
B15: Probe and thermometer | C15: Manager’s office | D15: Y | E15: 06-03-2026 | F15: 12 | G15: 46477 | H15: OBS T2.2b | I15: Valid | J15: =G15-TODAY() -> 175
A16: AS00111 | B16: B Drying oven | C16: Prep area | D16: Y | E16: 11-12-2025 | F16: 12 | G16: 46387 | H16: NKOT MO2.5 A | I16: Valid | J16: =G16-TODAY() -> 85

Sheet Staff Competency
A1: ISO/IEC 17025:2017 QMS DASHBOARD | STAFF COMPETENCY
A2: Blue-font cells are example/input rows — overwrite or extend with your own records. Do not delete the header row or column structure (dashboard formulas depend on it).
A3: Legend: Blue text = example data to edit | Black text = formula (auto-calculated) — do not overwrite.
A5: Staff Name | B5: Position | C5: Test Method / Scope | D5: Current Competency Date | E5: Reassessment Interval (Months) | F5: Next Assessment Due | G5: Status | H5: Assessor | I5: Initial Witnessing Testing (Y/N) | J5: Remarks
A6: S Nyambi | B6: Lab Manager | C6: ISO/Quick Ash | D6: 46279 | E6: 12 | F6: =D6+E6*30 -> 46639 | G6: =IF(F6<TODAY(),"Overdue",IF(F6<TODAY()+60,"Due Soon","Competent")) -> Competent | H6: Operations Manager | I6: Y | J6: Initial assessment can be found in the competency file | N6: Lab Tech | O6: Operator | P6: Lab Supe | Q6: Lab Man | R6: Ope Man
C7: Inherent Moisture | D7: 46279 | E7: 12 | F7: =D7+E7*30 -> 46639 | G7: =IF(F7<TODAY(),"Overdue",IF(F7<TODAY()+60,"Due Soon","Competent")) -> Competent | H7: Operations Manager | I7: Y | J7: Initial assessment can be found in the competency file
C8: Volatile Matter | D8: 46279 | E8: 12 | F8: =D8+E8*30 -> 46639 | G8: =IF(F8<TODAY(),"Overdue",IF(F8<TODAY()+60,"Due Soon","Competent")) -> Competent | H8: Operations Manager | I8: Y | J8: Initial assessment can be found in the competency file
C9: Calorific Value | D9: 46279 | E9: 12 | F9: =D9+E9*30 -> 46639 | G9: =IF(F9<TODAY(),"Overdue",IF(F9<TODAY()+60,"Due Soon","Competent")) -> Competent | H9: Operations Manager | I9: Y | J9: Initial assessment can be found in the competency file
C10: Total Moisture | E10: 12 | F10: =D10+E10*30 -> 360 | G10: =IF(F10<TODAY(),"Overdue",IF(F10<TODAY()+60,"Due Soon","Competent")) -> Overdue | H10: Operations Manager | I10: Y | J10: Initial assessment can be found in the competency file
C11: PSD | E11: 12 | F11: =D11+E11*30 -> 360 | G11: =IF(F11<TODAY(),"Overdue",IF(F11<TODAY()+60,"Due Soon","Competent")) -> Overdue | H11: Operations Manager | I11: Y | J11: Initial assessment can be found in the competency file
C12: Washability | E12: 12 | F12: =D12+E12*30 -> 360 | G12: =IF(F12<TODAY(),"Overdue",IF(F12<TODAY()+60,"Due Soon","Competent")) -> Overdue | H12: Operations Manager | I12: Y | J12: Initial assessment can be found in the competency file
C13: Sample Prep | D13: 46279 | E13: 12 | F13: =D13+E13*30 -> 46639 | G13: =IF(F13<TODAY(),"Overdue",IF(F13<TODAY()+60,"Due Soon","Competent")) -> Competent | H13: Operations Manager | I13: Y | J13: Initial assessment can be found in the competency file
C14: Technical Sign | D14: 46279 | E14: 12 | F14: =D14+E14*30 -> 46639 | G14: =IF(F14<TODAY(),"Overdue",IF(F14<TODAY()+60,"Due Soon","Competent")) -> Competent | H14: Operations Manager | I14: Y | J14: Initial assessment can be found in the competency file
A17: G Chisali | B17: Lab Supervisor | C17: ISO/Quick Ash | E17: 12 | F17: =D17+E17*30 -> 360 | G17: =IF(F17<TODAY(),"Overdue",IF(F17<TODAY()+60,"Due Soon","Competent")) -> Overdue | H17: Lab Manager | N17: ISO Ash | O17: Sample prep | P17: ISO Ash | Q17: ISO Ash | R17: ISO Ash
C18: Inherent Moisture | E18: 12 | F18: =D18+E18*30 -> 360 | G18: =IF(F18<TODAY(),"Overdue",IF(F18<TODAY()+60,"Due Soon","Competent")) -> Overdue | H18: Lab Manager
C19: Volatile Matter | E19: 12 | F19: =D19+E19*30 -> 360 | G19: =IF(F19<TODAY(),"Overdue",IF(F19<TODAY()+60,"Due Soon","Competent")) -> Overdue | H19: Lab Manager
C20: Calorific Value | E20: 12 | F20: =D20+E20*30 -> 360 | G20: =IF(F20<TODAY(),"Overdue",IF(F20<TODAY()+60,"Due Soon","Competent")) -> Overdue | H20: Lab Manager
C21: Total Moisture | E21: 12 | F21: =D21+E21*30 -> 360 | G21: =IF(F21<TODAY(),"Overdue",IF(F21<TODAY()+60,"Due Soon","Competent")) -> Overdue | H21: Lab Manager
C22: PSD | E22: 12 | F22: =D22+E22*30 -> 360 | G22: =IF(F22<TODAY(),"Overdue",IF(F22<TODAY()+60,"Due Soon","Competent")) -> Overdue | H22: Lab Manager
C23: Washability | E23: 12 | F23: =D23+E23*30 -> 360 | G23: Due Soon | H23: Lab Manager
A25: K Maleka | B25: Lab Analyst/ PT Coordinator | C25: ISO/Quick Ash | D25: 46279 | E25: 12 | F25: =D25+E25*30 -> 46639 | G25: =IF(F25<TODAY(),"Overdue",IF(F25<TODAY()+60,"Due Soon","Competent")) -> Competent | H25: Lab Manager | I25: Y | J25: Initial assessment can be found in the competency file | N25: ISO VM | O25: TM | P25: ISO VM | Q25: ISO VM | R25: ISO VM
C26: Inherent Moisture | D26: 46279 | E26: 12 | F26: =D26+E26*30 -> 46639 | G26: =IF(F26<TODAY(),"Overdue",IF(F26<TODAY()+60,"Due Soon","Competent")) -> Competent | H26: Lab Manager | I26: Y | J26: Initial assessment can be found in the competency file
C27: Volatile Matter | D27: 46279 | E27: 12 | F27: =D27+E27*30 -> 46639 | G27: =IF(F27<TODAY(),"Overdue",IF(F27<TODAY()+60,"Due Soon","Competent")) -> Competent | H27: Lab Manager | I27: Y | J27: Initial assessment can be found in the competency file
C28: Calorific Value | D28: 46279 | E28: 12 | F28: =D28+E28*30 -> 46639 | G28: =IF(F28<TODAY(),"Overdue",IF(F28<TODAY()+60,"Due Soon","Competent")) -> Competent | H28: Lab Manager | I28: Y | J28: Initial assessment can be found in the competency file
A30: N Hlongwane | B30: Lab Analyst/ PT Coordinator | C30: ISO/Quick Ash | D30: 46279 | E30: 12 | F30: =D30+E30*30 -> 46639 | G30: =IF(F30<TODAY(),"Overdue",IF(F30<TODAY()+60,"Due Soon","Competent")) -> Competent | H30: Lab Manager | I30: Y | J30: Initial assessment can be found in the competency file | N30: ISO IM | O30: PSD | P30: ISO IM | Q30: ISO IM | R30: ISO IM
C31: Inherent Moisture | D31: 46279 | E31: 12 | F31: =D31+E31*30 -> 46639 | G31: =IF(F31<TODAY(),"Overdue",IF(F31<TODAY()+60,"Due Soon","Competent")) -> Competent | H31: Lab Manager | I31: Y | J31: Initial assessment can be found in the competency file | N31: ISO CV | O31: Wash | P31: ISO CV | Q31: ISO CV | R31: ISO CV
C32: Volatile Matter | D32: 46279 | E32: 12 | F32: =D32+E32*30 -> 46639 | G32: =IF(F32<TODAY(),"Overdue",IF(F32<TODAY()+60,"Due Soon","Competent")) -> Competent | H32: Lab Manager | I32: Y | J32: Initial assessment can be found in the competency file | N32: Q-ash | P32: Sample prep | Q32: Sample prep | R32: Sample prep
C33: Calorific Value | D33: 46279 | E33: 12 | F33: =D33+E33*30 -> 46639 | G33: =IF(F33<TODAY(),"Overdue",IF(F33<TODAY()+60,"Due Soon","Competent")) -> Competent | H33: Lab Manager | I33: Y | J33: Initial assessment can be found in the competency file | P33: Q-ash | Q33: Reporting | R33: Reporting
A35: N Nyambi | B35: Lab Operator | C35: Sample Prep | D35: 46286 | E35: 12 | F35: =D35+E35*30 -> 46646 | G35: =IF(F35<TODAY(),"Overdue",IF(F35<TODAY()+60,"Due Soon","Competent")) -> Competent | H35: Snr Analyst | I35: N
C36: Total Moisture | D36: 46286 | E36: 12 | F36: =D36+E36*30 -> 46646 | G36: =IF(F36<TODAY(),"Overdue",IF(F36<TODAY()+60,"Due Soon","Competent")) -> Competent | H36: Snr Analyst | I36: N
C37: PSD | D37: 46286 | E37: 12 | F37: =D37+E37*30 -> 46646 | G37: =IF(F37<TODAY(),"Overdue",IF(F37<TODAY()+60,"Due Soon","Competent")) -> Competent | H37: Snr Analyst | I37: N
A39: K Tshabalala | B39: Lab Operator | C39: Sample Prep | D39: 46286 | E39: 12 | F39: =D39+E39*30 -> 46646 | G39: =IF(F39<TODAY(),"Overdue",IF(F39<TODAY()+60,"Due Soon","Competent")) -> Competent | H39: Snr Analyst | I39: N
C40: Total Moisture | D40: 46286 | E40: 12 | F40: =D40+E40*30 -> 46646 | G40: =IF(F40<TODAY(),"Overdue",IF(F40<TODAY()+60,"Due Soon","Competent")) -> Competent | H40: Snr Analyst | I40: N | L40: Evidence check: | M40: Sample prep = Crusher eff, Pulve eff, TM, PSD, Wash, Balance verificatio
C41: PSD | D41: 46286 | E41: 12 | F41: =D41+E41*30 -> 46646 | G41: =IF(F41<TODAY(),"Overdue",IF(F41<TODAY()+60,"Due Soon","Competent")) -> Competent | H41: Snr Analyst | I41: N

Sheet Customer Feedback
A1: ISO/IEC 17025:2017 QMS DASHBOARD | CUSTOMER FEEDBACK
A2: Blue-font cells are example/input rows — overwrite or extend with your own records. Do not delete the header row or column structure (dashboard formulas depend on it).
A3: Legend: Blue text = example data to edit | Black text = formula (auto-calculated) — do not overwrite.
A5: Complaint No | B5: Date Received | C5: Customer | D5: Description | E5: Category | F5: Root Cause | G5: CAPA Ref | H5: Status | I5: Closure Date | J5: Days to Close | K5: Satisfaction Follow-up (Y/N)
A6: CMP-2026-01 | B6: 2026-02-12 | C6: Client - Contractor A | D6: Queried reported gradation values for aggregate sample | E6: Report Error | F6: Transcription error in report template | G6: CAPA-2026-04 | H6: Closed | I6: 2026-03-08 | J6: =I6-B6 -> 24 | K6: Y
A7: CMP-2026-02 | B7: 2026-03-25 | C7: Client - Consultant B | D7: Delay in turnaround for concrete cube results | E7: Turnaround Time | F7: Backlog during peak casting period | G7: - | H7: Closed | I7: 2026-04-02 | J7: =I7-B7 -> 8 | K7: Y
A8: CMP-2026-03 | B8: 2026-05-10 | C8: Client - Contractor C | D8: Questioned CBR test methodology applied on site samples | E8: Test Result | F8: Clarification only - method applied correctly per D1883 | G8: - | H8: Closed | I8: 2026-05-14 | J8: =I8-B8 -> 4 | K8: Y
A9: CMP-2026-04 | B9: 2026-06-02 | C9: Client - Consultant D | D9: Requested reissue of report with corrected project reference | E9: Service | F9: Administrative error on project code | G9: - | H9: Open | J9: =IF(I9="",TODAY()-B9,I9-B9) -> 127 | K9: N

Sheet Document Control
A1: ISO/IEC 17025:2017 QMS DASHBOARD | DOCUMENT CONTROL
A2: Blue-font cells are example/input rows — overwrite or extend with your own records. Do not delete the header row or column structure (dashboard formulas depend on it).
A3: Legend: Blue text = example data to edit | Black text = formula (auto-calculated) — do not overwrite.
A5: Doc No | B5: Document Title | C5: Type | D5: Version | E5: Issue Date | F5: Review Interval (Yrs) | G5: Review Due Date | H5: Status | I5: Approved By
G6: =E6+F6*365 -> 0 | H6: =IF(G6<TODAY(),"Overdue",IF(G6<TODAY()+90,"Due Soon","Current")) -> Overdue
G7: =E7+F7*365 -> 0 | H7: =IF(G7<TODAY(),"Overdue",IF(G7<TODAY()+90,"Due Soon","Current")) -> Overdue
G8: =E8+F8*365 -> 0 | H8: =IF(G8<TODAY(),"Overdue",IF(G8<TODAY()+90,"Due Soon","Current")) -> Overdue
G9: =E9+F9*365 -> 0 | H9: =IF(G9<TODAY(),"Overdue",IF(G9<TODAY()+90,"Due Soon","Current")) -> Overdue
G10: =E10+F10*365 -> 0 | H10: =IF(G10<TODAY(),"Overdue",IF(G10<TODAY()+90,"Due Soon","Current")) -> Overdue
G11: =E11+F11*365 -> 0 | H11: =IF(G11<TODAY(),"Overdue",IF(G11<TODAY()+90,"Due Soon","Current")) -> Overdue
G12: =E12+F12*365 -> 0 | H12: =IF(G12<TODAY(),"Overdue",IF(G12<TODAY()+90,"Due Soon","Current")) -> Overdue

Sheet Management Review
A1: ISO/IEC 17025:2017 QMS DASHBOARD | MANAGEMENT REVIEW
A2: Blue-font cells are example/input rows — overwrite or extend with your own records. Do not delete the header row or column structure (dashboard formulas depend on it).
A3: Legend: Blue text = example data to edit | Black text = formula (auto-calculated) — do not overwrite.
A5: Action No | B5: Meeting Date | C5: Clause 8.9 Input Area | D5: Decision / Action | E5: Responsible | F5: Target Date | G5: Status | H5: Closure Date
A6: MR-2026-01 | B6: 2026-01-30 | C6: NCR/CAPA Status Review | D6: Approve additional QA resource for review of high-risk reports | E6: Lab Director | F6: 2026-03-01 | G6: Closed | H6: 2026-02-25
A7: MR-2026-02 | B7: 2026-01-30 | C7: PT/ILC Performance | D7: Mandate refresher training for any unsatisfactory PT result within 30 days | E7: Technical Manager | F7: Ongoing | G7: Closed | H7: 2026-02-10
A8: MR-2026-03 | B8: 2026-01-30 | C8: Resource Adequacy | D8: Approve budget for second ductility bath to remove single point of failure | E8: Lab Director | F8: 2026-06-30 | G8: Open
A9: MR-2026-04 | B9: 2026-01-30 | C9: Risk & Opportunity (Cl. 8.5) | D9: Review supplier risk assessment for calibration providers | E9: QC Engineer | F9: 2026-04-30 | G9: Open

Sheet Chart Data
A1: Chart source data — auto-calculated. Do not edit.
A3: NCR Status
A4: Open | B4: =COUNTIFS('NCR Register'!K6:K54,"Open") -> 0
A5: Closed | B5: =COUNTIFS('NCR Register'!K6:K54,"Closed") -> 23
A7: NCR Severity
A8: Major | B8: =COUNTIFS('NCR Register'!F6:F54,"Major") -> 25
A9: Minor | B9: =COUNTIFS('NCR Register'!F6:F54,"Minor") -> 3
A11: NCR by Source
A12: Internal Audit | B12: =COUNTIFS('NCR Register'!C6:C54,"Internal Audit") -> 2
A13: Equipment | B13: =COUNTIFS('NCR Register'!C6:C54,"Equipment") -> 1
A14: PT/ILC | B14: =COUNTIFS('NCR Register'!C6:C54,"PT/ILC") -> 0
A15: Customer Complaint | B15: =COUNTIFS('NCR Register'!C6:C54,"Customer Complaint") -> 0
A16: Staff Observation | B16: =COUNTIFS('NCR Register'!C6:C54,"Staff Observation") -> 0
A17: Management Review | B17: =COUNTIFS('NCR Register'!C6:C54,"Management Review") -> 1
A19: CAPA Status
A20: Open | B20: =COUNTIFS('CAPA Tracker'!J6:J55,"Open") -> 2
A21: In Progress | B21: =COUNTIFS('CAPA Tracker'!J6:J55,"In Progress") -> 2
A22: Closed | B22: =COUNTIFS('CAPA Tracker'!J6:J55,"Closed") -> 4
A24: Internal Audit Findings (YTD)
A25: Major NC | B25: =SUM('Internal Audits'!E6:E55) -> 0
A26: Minor NC | B26: =SUM('Internal Audits'!F6:F55) -> 0
A27: OFI | B27: =SUM('Internal Audits'!G6:G55) -> 0
A29: Calibration Status
A30: Valid | B30: =COUNTIFS(Calibration!I6:I53,"Valid") -> 11
A31: Due Soon | B31: =COUNTIFS(Calibration!I6:I53,"Due Soon") -> 0
A32: Overdue | B32: =COUNTIFS(Calibration!I6:I53,"Overdue") -> 0
A34: Staff Competency Status
A35: Competent | B35: =COUNTIFS('Staff Competency'!G6:G80,"Competent") -> 20
A36: Due Soon | B36: =COUNTIFS('Staff Competency'!G6:G80,"Due Soon") -> 1
A37: Overdue | B37: =COUNTIFS('Staff Competency'!G6:G80,"Overdue") -> 9
A39: PT-ILC Performance
A40: Satisfactory | B40: =COUNTIFS('PT-ILC'!F6:F55,"Satisfactory") -> 0
A41: Questionable | B41: =COUNTIFS('PT-ILC'!F6:F55,"Questionable") -> 0
A42: Unsatisfactory | B42: =COUNTIFS('PT-ILC'!F6:F55,"Unsatisfactory") -> 0
A44: NCR Aging (Open items, days since raised)
A45: 'NCR Register'!A6 | B45: =IF('NCR Register'!K6="Open",TODAY()-'NCR Register'!B6,"")
A46: 'NCR Register'!A7 | B46: =IF('NCR Register'!K7="Open",TODAY()-'NCR Register'!B7,"")
A47: 'NCR Register'!A8 | B47: =IF('NCR Register'!K8="Open",TODAY()-'NCR Register'!B8,"")
A48: 'NCR Register'!A9 | B48: =IF('NCR Register'!K9="Open",TODAY()-'NCR Register'!B9,"")
A49: 'NCR Register'!A10 | B49: =IF('NCR Register'!K10="Open",TODAY()-'NCR Register'!B10,"")
...
