Workbook

Sheet Instructions
B3: INSTRUCTIONS FOR USING THE CONTROL CHART SPREADSHEET
B5: A | C5: Conditioning New Control Material
C6: 1 | D6: Ensure that the control sample is conditioned for a minimum of four hours before re-bottling
C7: 2 | D7: Ensure an additional control sample bottle is conditioned for each work area and this is held as a reserve
C8: 3 | D8: When this reserve bottle is issued a new bottle shall be conditioned and held in reserve
C9: 4 | D9: Ensure to complete the conditioning log book and the CRM control log book
C10: 5 | D10: Clearly mark the bottle with unique Control ID, Example CRM033 (1) Opened 10/10/17, Conditioned 10/10/17, Expiry 10/10/19, PROX
D11: Key | E11: CRM033 | F11: Is the batch number
E12: (1) | F12: Is a unique number for the bottle. Each number within the batch will have a different number and be recorded in the CRM control log book
E13: Opened | F13: Is the date opened
E14: Conditioned | F14: Is the date conditioned and shall be the date of opening
E15: Expiry | F15: Is the date of expiry, which shall be two years from date of opening unless otherwise specified on the certificate
E16: PROX | F16: Is the location that the CRM shall be used (work areas shall be PROX, CV, and Sulphur)
B18: B | C18: Analysing New Control Material
C20: 1 | D20: On the Data Input tab enter all the information from the CRM certificate : the certified value and limits for on air dry and dry base. Do this for all parameters
C21: 2 | D21: Run 20 to 30 controls on different days using different instruments and analysts in order to establish new limits
C22: 3 | D22: Remember to records results on an air dry basis
C23: 4 | D23: Enter the results on the data input tab under the correct parameter. For ALL parameters enter results to 2 decimal places. Enter data only in the Yellow Cells
C24: 5 | D24: Data will be automatically checked for outliers and compliance with Reproducibility limit
C25: 6 | D25: If any failures, results will indicate in RED -- Remove these as they are statistical outlier
C26: 7 | D26: When outlier test passes, and any outliers removed, there may still be an issue with reproducibility limit failures. To assist in identifying the following will happen:
D27: The lowest remaning value will flag in blue
D28: The highest remaining value will flag in orange
C29: 8 | D29: Use these flags to identify and repeat or remove these values until the repeatability limit is satisfied. NOTE, use your judgement carefully. If you are having to remove/repeat more than 3-4 points then it is likely there is an underlying issue that you will need to investigate further.
C30: 9 | D30: The spreadsheet will automatically calculate your assigned value and compare it with the certified values for the CRM
C31: 10 | D31: If your results do not compare to the certificated values they will be highlighted in red. You will need to repeat until results are within the limits
C32: 11 | D32: You will need a minimum of 20 data points to validate your new control chart
C33: 12 | D33: If all criteria is met, the data will automatically transfer to the Plot data tab. NOTE data will not transfer if there is an outlier, reproducibility limit failure or your results do not agree with the certified ranges for both air dry and dry base
C34: 13 | D34: The plot data will automatically transfer to the corresponding chart eg "ISO Ash Chart" tab
B36: C | C36: Printing your new control chart
C37: 1 | D37: Each control chart is on a green tab
C38: 2 | D38: The row height and column width is preset to optimise printing
C39: 3 | D39: The print area, page layout, and margins are set up for a Brother MFC-L2740DW printer
C40: 4 | D40: If you have a different printer please change the margins as per appendix below
C41: 5 | D41: Should row heights or column widths have change please refer to Appendix for setting on key cells
B43: D | C43: Using your new control chart
C44: 1 | D44: Write the name/number of the Analyser, Instrument, Oven or Furnace at the top of the sheet
C45: 2 | D45: Enter the date, analyst name, dup 1 value and dup 2 value in the table at the top of the sheet
C46: 3 | D46: Calculate the average x and range and enter in the table at the top of the sheet
C47: 4 | D47: Plot the average value in the top graph
...

Sheet Data Input
B1: Statistical Evaluation of Results
B3: Function | H3: Test | M3: Criteria
B4: Outliers | H4: Dixon Q Test at 95% Confidence Limit | M4: Qcalc < Qcrit (95% CL)
B5: Reproducibility (r) | H5: Reproducibility Limit of method | M5: ractual < rmethod
E7: ENTER RESULTS IN YELLOW FIELD
G8: ='Data Input'!E40:E73 -> #VALUE!
B9: Parameter | F9: Calorific Value | J9: Parameter | N9: Total Sulphur - Low | R9: Parameter | V9: MIAS | Z9: Parameter | AD9: Volatile Matter | AH9: Parameter | AL9: ISO Ash | AP9: Parameter | AT9: Quick Ash | AY9: Parameter | BC9: CV - Benzoic
B10: CRM Certified Values | J10: CRM Certified Values | R10: CRM Certified Values | Z10: CRM Certified Values | AH10: CRM Certified Values | AP10: CRM Certified Values | AY10: CRM Certified Values
B11: Control ID: | F11: AS CRM 002 | J11: Control ID: | N11: AS CRM 002 | R11: Control ID: | V11: AS CRM 002 | Z11: Control ID: | AD11: AS CRM 002 | AH11: Control ID: | AL11: AS CRM 002 | AP11: Control ID: | AT11: AS CRM 002 | AY11: Control ID: | BC11: Benzoic Acid
B12: Certified Values (Air Dry) | J12: Certified Values (Air Dry) | R12: Certified Values (Air Dry) | Z12: Certified Values (Air Dry) | AH12: Certified Values (Air Dry) | AP12: Certified Values (Air Dry) | AY12: Certified Values (Air Dry)
B13: Certified value | F13: 25.96 | J13: Certified value | N13: 0.38 | R13: Certified value | V13: N/A | Z13: Certified value | AD13: 26.2 | AH13: Certified value | AL13: 14.27 | AP13: Certified value | AT13: 14.38 | AY13: Certified value | BC13: 1.69
B14: Maximum | F14: 26.04 | J14: Maximum | N14: 0.42 | R14: Maximum | Z14: Maximum | AD14: 26.3 | AH14: Maximum | AL14: 14.35 | AP14: Maximum | AT14: 14.53 | AY14: Maximum | BC14: 1.79
B15: Minimum | F15: 25.88 | J15: Minimum | N15: 0.34 | R15: Minimum | Z15: Minimum | AD15: 26.1 | AH15: Minimum | AL15: 14.19 | AP15: Minimum | AT15: 14.23 | AY15: Minimum | BC15: 1.59
B16: Certified Values (Dry Base) | J16: Certified Values (Dry Base) | R16: Certified Values (Dry Base) | Z16: Certified Values (Dry Base) | AH16: Certified Values (Dry Base) | AP16: Certified Values (Dry Base) | AY16: Certified Values (Dry Base)
B17: Certified value | F17: 27.1 | J17: Certified value | N17: 0.4 | R17: Certified value | V17: N/A | Z17: Certified value | AD17: 27.34 | AH17: Certified value | AL17: 14.9 | AP17: Certified value | AT17: 15.06 | AY17: Certified value | BC17: 1.76
B18: Standard Deviation | F18: 0.08 | J18: Standard Deviation | N18: 0.04 | R18: Standard Deviation | Z18: Standard Deviation | AD18: 0.1 | AH18: Standard Deviation | AL18: 0.08 | AP18: Standard Deviation | AT18: 0.15 | AY18: Standard Deviation | BC18: 0.048
B19: Maximum | F19: =F17+F18 -> 27.18 | J19: Maximum | N19: =N17+N18 -> 0.44 | R19: Maximum | Z19: Maximum | AD19: =AD17+AD18 -> 27.44 | AH19: Maximum | AL19: =AL17+AL18 -> 14.98 | AP19: Maximum | AT19: =AT17+AT18 -> 15.21 | AY19: Maximum | BC19: =BC17+BC18 -> 1.808
B20: Minimum | F20: =F17-F18 -> 27.02 | J20: Minimum | N20: =N17-N18 -> 0.36 | R20: Minimum | Z20: Minimum | AD20: =AD17-AD18 -> 27.24 | AH20: Minimum | AL20: =AL17-AL18 -> 14.82 | AP20: Minimum | AT20: =AT17-AT18 -> 14.91 | AY20: Minimum | BC20: =BC17-BC18 -> 1.712
B22: Laboratory Results | J22: Laboratory Results | R22: Laboratory Results | Z22: Laboratory Results | AH22: Laboratory Results | AP22: Laboratory Results | AY22: Laboratory Results
B23: Laboratory Average (Air Dry) | F23: =IF(ISNUMBER(H89),H89,"") -> 25.894231 | J23: Laboratory Average (Air Dry) | N23: =IF(ISNUMBER(P89),P89,"") -> 0.39 | R23: Laboratory Average (Air Dry) | V23: =IF(ISNUMBER(X89),X89,"") -> 4.1353846 | Z23: Laboratory Average -Moisture Corrected (Air Dry) | AD23: =IF(AND(ISNUMBER(AF89),ISNUMBER(V23)),(AF89-V23)) -> 26.271923 | AH23: Laboratory Average (Air Dry) | AL23: =IF(ISNUMBER(AN89),AN89,"") -> 14.193846 | AP23: Laboratory Average (Air Dry) | AT23: =IF(ISNUMBER(AV89),AV89,"") -> 13.753846 | AY23: Laboratory Average (Air Dry) | BC23: =IF(ISNUMBER(BE89),BE89,"")
B24: Laboratory Average (Air Dry) Pass/Fail | F24: =IF(ISNUMBER(F23),IF(F23>F14,"FAIL-HIGH",IF(F23<F15,"FAIL-LOW","PASS"))) -> PASS | J24: Laboratory Average (Air Dry) Pass/Fail | N24: =IF(ISNUMBER(N23),IF(N23>N14,"FAIL-HIGH",IF(N23<N15,"FAIL-LOW","PASS"))) -> PASS | R24: Laboratory Average (Air Dry) Pass/Fail | V24: N/A | Z24: Laboratory Average (Air Dry) Pass/Fail | AD24: =IF(ISNUMBER(AD23),IF(AD23>AD14,"FAIL-HIGH",IF(AD23<AD15,"FAIL-LOW","PASS"))) -> PASS | AH24: Laboratory Average (Air Dry) Pass/Fail | AL24: =IF(ISNUMBER(AL23),IF(AL23>AL14,"FAIL-HIGH",IF(AL23<AL15,"FAIL-LOW","PASS"))) -> PASS | AP24: Laboratory Average (Air Dry) Pass/Fail | AT24: =IF(ISNUMBER(AT23),IF(AT23>AT14,"FAIL-HIGH",IF(AT23<AT15,"FAIL-LOW","PASS"))) -> FAIL-LOW | AY24: Laboratory Average (Air Dry) Pass/Fail | BC24: =IF(ISNUMBER(BC23),IF(BC23>BC14,"FAIL-HIGH",IF(BC23<BC15,"FAIL-LOW","PASS"))) -> FALSE
B25: Laboratory Average (Dry Base) | F25: =IF(ISNUMBER($V$23),(100*F23)/(100-$V$23),"NO MIAS RESULT") -> 27.01125 | J25: Laboratory Average (Dry Base) | N25: =IF(ISNUMBER($V$23),(100*N23)/(100-$V$23),"NO MIAS RESULT") -> 0.40682373 | R25: Laboratory Average (Dry Base) | Z25: Laboratory Average- Moisture Corrected (Dry Base) | AD25: =IF(ISNUMBER($V$23),(100*AD23)/(100-$V$23),"NO MIAS RESULT") -> 27.405235 | AH25: Laboratory Average (Dry Base) | AL25: =IF(ISNUMBER($V$23),(100*AL23)/(100-$V$23),"NO MIAS RESULT") -> 14.806137 | AP25: Laboratory Average (Dry Base) | AT25: =IF(ISNUMBER($V$23),(100*AT23)/(100-$V$23),"NO MIAS RESULT") -> 14.347156 | AY25: Laboratory Average (Dry Base) | BC25: =IF(ISNUMBER($V$23),(100*BC23)/(100-$V$23),"NO MIAS RESULT") -> #VALUE!
B26: Laboratory Average (Dry Base) Pass/Fail | F26: =IF(F25="NO MIAS RESULT","NO MIAS RESULT",IF(ISNUMBER(F25),IF(F25>F19,"FAIL-HIGH",IF(F25<F20,"FAIL-LOW","PASS")))) -> FAIL-LOW | J26: Laboratory Average (Dry Base) Pass/Fail | N26: =IF(N25="NO MIAS RESULT","NO MIAS RESULT",IF(ISNUMBER(N25),IF(N25>N19,"FAIL-HIGH",IF(N25<N20,"FAIL-LOW","PASS")))) -> PASS | R26: Laboratory Average (Dry Base) Pass/Fail | Z26: Laboratory Average (Dry Base) Pass/Fail | AD26: =IF(AD25="NO MIAS RESULT","NO MIAS RESULT",IF(ISNUMBER(AD25),IF(AD25>AD19,"FAIL-HIGH",IF(AD25<AD20,"FAIL-LOW","PASS")))) -> PASS | AH26: Laboratory Average (Dry Base) Pass/Fail | AL26: =IF(AL25="NO MIAS RESULT","NO MIAS RESULT",IF(ISNUMBER(AL25),IF(AL25>AL19,"FAIL-HIGH",IF(AL25<AL20,"FAIL-LOW","PASS")))) -> FAIL-LOW | AP26: Laboratory Average (Dry Base) Pass/Fail | AT26: =IF(AT25="NO MIAS RESULT","NO MIAS RESULT",IF(ISNUMBER(AT25),IF(AT25>AT19,"FAIL-HIGH",IF(AT25<AT20,"FAIL-LOW","PASS")))) -> FAIL-LOW | AY26: Laboratory Average (Dry Base) Pass/Fail | BC26: =IF(BC25="NO MIAS RESULT","NO MIAS RESULT",IF(ISNUMBER(BC25),IF(BC25>BC19,"FAIL-HIGH",IF(BC25<BC20,"FAIL-LOW","PASS")))) -> #VALUE!
B28: Outlier and Reproducibility Tests | J28: Outlier and Reproducibility Tests | R28: Outlier and Reproducibility Tests | Z28: Outlier and Reproducibility Tests | AH28: Outlier and Reproducibility Tests | AP28: Outlier and Reproducibility Tests | AY28: Outlier and Reproducibility Tests
B29: Qcalc | F29: =MAX(H96:H97) -> 0.046511628 | J29: Qcalc | N29: =MAX(P96:P97) -> 0.2 | R29: Qcalc | V29: =MAX(X96:X97) -> 0.25 | Z29: Qcalc | AD29: =MAX(AF96:AF97) -> 0.11111111 | AH29: Qcalc | AL29: =MAX(AN96:AN97) -> 0.15 | AP29: Qcalc | AT29: =MAX(AV96:AV97) -> 6.25e-05 | AY29: Qcalc | BC29: =MAX(BE96:BE97) -> #N/A
B30: Qcrit (95% CL) | F30: =VLOOKUP(H88,$BG$40:$BH$85,2,FALSE) -> 0.436 | J30: Qcrit (95% CL) | N30: =VLOOKUP(P88,$BG$40:$BH$85,2,FALSE) -> 0.443 | R30: Qcrit (95% CL) | V30: =VLOOKUP(X88,$BG$40:$BH$85,2,FALSE) -> 0.436 | Z30: Qcrit (95% CL) | AD30: =VLOOKUP(AF88,$BG$40:$BH$85,2,FALSE) -> 0.436 | AH30: Qcrit (95% CL) | AL30: =VLOOKUP(AN88,$BG$40:$BH$85,2,FALSE) -> 0.436 | AP30: Qcrit (95% CL) | AT30: =VLOOKUP(AV88,$BG$40:$BH$85,2,FALSE) -> 0.436 | AY30: Qcrit (95% CL) | BC30: =VLOOKUP(BE88,$BG$40:$BH$85,2,FALSE) -> #N/A
B31: Outliers | F31: =IF(F29>F30,"Yes","No") -> No | J31: Outliers | N31: =IF(N29>N30,"Yes","No") -> No | R31: Outliers | V31: =IF(V29>V30,"Yes","No") -> No | Z31: Outliers | AD31: =IF(AD29>AD30,"Yes","No") -> No | AH31: Outliers | AL31: =IF(AL29>AL30,"Yes","No") -> No | AP31: Outliers | AT31: =IF(AT29>AT30,"Yes","No") -> No | AY31: Outliers | BC31: =IF(BC29>BC30,"Yes","No") -> #N/A
B32: Outlier value MAX | F32: =IF(H96>F30,H92,"") | J32: Outlier value MAX | N32: =IF(P96>N30,P92,"") | R32: Outlier value MAX | V32: =IF(X96>V30,X92,"") | Z32: Outlier value MAX | AD32: =IF(AF96>AD30,AF92,"") | AH32: Outlier value MAX | AL32: =IF(AN96>AL30,AN92,"") | AP32: Outlier value MAX | AT32: =IF(AV96>AT30,AV92,"") | AY32: Outlier value MAX | BC32: =IF(BE96>BC30,BE92,"") -> #N/A
B33: Outlier value MIN | F33: =IF(H97>F30,H91,"") | J33: Outlier value MIN | N33: =IF(P97>N30,P91,"") | R33: Outlier value MIN | V33: =IF(X97>V30,X91,"") | Z33: Outlier value MIN | AD33: =IF(AF97>AD30,AF91,"") | AH33: Outlier value MIN | AL33: =IF(AN97>AL30,AN91,"") | AP33: Outlier value MIN | AT33: =IF(AV97>AT30,AV91,"") | AY33: Outlier value MIN | BC33: =IF(BE97>BC30,BE91,"") -> #N/A
B34: Data Range (Actual Reproducibility) | F34: =H93 -> 0.43 | J34: Data Range (Actual Reproducibility) | N34: =P93 -> 0.1 | R34: Data Range (Actual Reproducibility) | V34: =X93 -> 0.8 | Z34: Data Range (Actual Reproducibility) | AD34: =AF93 -> 0.9 | AH34: Data Range (Actual Reproducibility) | AL34: =AN93 -> 0.4 | AP34: Data Range (Actual Reproducibility) | AT34: =AV93 -> 1.6 | AY34: Data Range (Actual Reproducibility) | BC34: =BE93 -> 0
B35: Reproducibility | F35: =IF(H93="","",IF(H93>F36,"FAIL","PASS")) -> PASS | J35: Reproducibility | N35: =IF(P93="","",IF(P93>N36,"FAIL","PASS")) -> PASS | R35: Reproducibility | V35: N/A | Z35: Reproducibility | AD35: =IF(AF93="","",IF(AF93>AD36,"FAIL","PASS")) -> PASS | AH35: Reproducibility | AL35: =IF(AN93="","",IF(AN93>AL36,"FAIL","PASS")) -> PASS | AP35: Reproducibility | AT35: =IF(AV93="","",IF(AV93>AT36,"FAIL","PASS")) -> FAIL | AY35: Reproducibility | BC35: =IF(BE93="","",IF(BE93>BC36,"FAIL","PASS")) -> PASS
B36: Reproducibility Limit | F36: 0.6 | G36: 0.3 | J36: Reproducibility Limit | N36: 0.1 | O36: =(0.02+(0.09*P89))+(0.00000001*P89) -> 0.055100004 | R36: Reproducibility Limit | V36: No Standard Limits | Z36: Reproducibility Limit | AD36: =IF(AF92>=10,(MAX((0.04*AF89),0.5)),0.5) -> 1.2162923 | AH36: Reproducibility Limit | AL36: =IF(AN89>=10,(0.03*AN89),0.3) -> 0.42581538 | AP36: Reproducibility Limit | AT36: =IF(AV89>=10,(0.03*AV89),0.3) -> 0.41261538 | AY36: Reproducibility Limit | BC36: 0.1 | BD36: =(0.02+(0.09*BE89))+(0.00000001*BE89) -> #DIV/0!
B38: Replicate Laboratory Data | J38: Replicate Laboratory Data | R38: Replicate Laboratory Data | Z38: Replicate Laboratory Data | AH38: Replicate Laboratory Data | AP38: Replicate Laboratory Data | AY38: Replicate Laboratory Data
B39: Number | C39: Date | D39: Instrument | E39: Analyst | F39: Rank | G39: Tiebreak Result | H39: Result | J39: Number | K39: Date | L39: Instrument | M39: Analyst | N39: Rank | O39: Tiebreak Result | P39: Result | R39: Number | S39: Date | T39: Instrument | U39: Analyst | V39: Rank | W39: Tiebreak Result | X39: Result | Z39: Number | AA39: Date | AB39: Instrument | AC39: Analyst | AD39: Rank | AE39: Tiebreak Result | AF39: Result | AH39: Number | AI39: Date | AJ39: Instrument | AK39: Analyst | AL39: Rank | AM39: Tiebreak Result | AN39: Result | AP39: Number | AQ39: Date | AR39: Instrument | AS39: Analyst | AT39: Rank | AU39: Tiebreak Result | AV39: Result | AY39: Number | AZ39: Date | BA39: Instrument | BB39: Analyst | BC39: Rank | BD39: Tiebreak Result | BE39: Result | BG39: Dixon Q Table (95% CL)
B40: 1 | F40: =IF(G40="","",RANK(G40,$G$40:$G$87)) -> 11 | G40: =IF(H40="","",(COUNTIF($H$40:H40,H40)-1)*0.0001+H40) -> 25.95 | H40: 25.95 | J40: 1 | N40: =IF(O40="","",RANK(O40,$O$40:$O$87)) -> 17 | O40: =IF(P40="","",(COUNTIF($P$40:P40,P40)-1)*0.0001+P40) -> 0.38 | P40: 0.38 | R40: 1 | V40: =IF(W40="","",RANK(W40,$W$40:$W$87)) -> 17 | W40: =IF(X40="","",(COUNTIF($X$40:X40,X40)-1)*0.0001+X40) -> 4.1 | X40: 4.1 | Z40: 1 | AD40: =IF(AE40="","",RANK(AE40,$AE$40:$AE$87)) -> 17 | AE40: =IF(AF40="","",(COUNTIF($AF$40:AF40,AF40)-1)*0.0001+AF40) -> 30.3 | AF40: 30.3 | AH40: 1 | AL40: =IF(AM40="","",RANK(AM40,$AM$40:$AM$87)) -> 16 | AM40: =IF(AN40="","",(COUNTIF($AN$40:AN40,AN40)-1)*0.0001+AN40) -> 14.2 | AN40: 14.2 | AP40: 1 | AT40: =IF(AU40="","",RANK(AU40,$AU$40:$AU$87)) -> 18 | AU40: =IF(AV40="","",(COUNTIF($AV$40:AV40,AV40)-1)*0.0001+AV40) -> 13.4 | AV40: 13.4 | AY40: 1 | BC40: =IF(BD40="","",RANK(BD40,#REF!)) | BD40: =IF(BE40="","",(COUNTIF($AX$40:BE40,BE40)-1)*0.0001+BE40) | BG40: 3 | BH40: 0.97
B41: 2 | F41: =IF(G41="","",RANK(G41,$G$40:$G$87)) -> 22 | G41: =IF(H41="","",(COUNTIF($H$40:H41,H41)-1)*0.0001+H41) -> 25.79 | H41: 25.79 | J41: 2 | N41: =IF(O41="","",RANK(O41,$O$40:$O$87)) -> 25 | O41: =IF(P41="","",(COUNTIF($P$40:P41,P41)-1)*0.0001+P41) -> 0.35 | P41: 0.35 | R41: 2 | V41: =IF(W41="","",RANK(W41,$W$40:$W$87)) -> 7 | W41: =IF(X41="","",(COUNTIF($X$40:X41,X41)-1)*0.0001+X41) -> 4.23 | X41: 4.23 | Z41: 2 | AD41: =IF(AE41="","",RANK(AE41,$AE$40:$AE$87)) -> 12 | AE41: =IF(AF41="","",(COUNTIF($AF$40:AF41,AF41)-1)*0.0001+AF41) -> 30.45 | AF41: 30.45 | AH41: 2 | AL41: =IF(AM41="","",RANK(AM41,$AM$40:$AM$87)) -> 19 | AM41: =IF(AN41="","",(COUNTIF($AN$40:AN41,AN41)-1)*0.0001+AN41) -> 14.12 | AN41: 14.12 | AP41: 2 | AT41: =IF(AU41="","",RANK(AU41,$AU$40:$AU$87)) -> 17 | AU41: =IF(AV41="","",(COUNTIF($AV$40:AV41,AV41)-1)*0.0001+AV41) -> 13.4001 | AV41: 13.4 | AY41: 2 | BC41: =IF(BD41="","",RANK(BD41,#REF!)) | BD41: =IF(BE41="","",(COUNTIF($AX$40:BE41,BE41)-1)*0.0001+BE41) | BG41: 4 | BH41: 0.829
B42: 3 | F42: =IF(G42="","",RANK(G42,$G$40:$G$87)) -> 14 | G42: =IF(H42="","",(COUNTIF($H$40:H42,H42)-1)*0.0001+H42) -> 25.93 | H42: 25.93 | J42: 3 | N42: =IF(O42="","",RANK(O42,$O$40:$O$87)) -> 21 | O42: =IF(P42="","",(COUNTIF($P$40:P42,P42)-1)*0.0001+P42) -> 0.37 | P42: 0.37 | R42: 3 | V42: =IF(W42="","",RANK(W42,$W$40:$W$87)) -> 5 | W42: =IF(X42="","",(COUNTIF($X$40:X42,X42)-1)*0.0001+X42) -> 4.3 | X42: 4.3 | Z42: 3 | AD42: =IF(AE42="","",RANK(AE42,$AE$40:$AE$87)) -> 10 | AE42: =IF(AF42="","",(COUNTIF($AF$40:AF42,AF42)-1)*0.0001+AF42) -> 30.6 | AF42: 30.6 | AH42: 3 | AL42: =IF(AM42="","",RANK(AM42,$AM$40:$AM$87)) -> 15 | AM42: =IF(AN42="","",(COUNTIF($AN$40:AN42,AN42)-1)*0.0001+AN42) -> 14.2001 | AN42: 14.2 | AP42: 3 | AT42: =IF(AU42="","",RANK(AU42,$AU$40:$AU$87)) -> 26 | AU42: =IF(AV42="","",(COUNTIF($AV$40:AV42,AV42)-1)*0.0001+AV42) -> 13.1 | AV42: 13.1 | AY42: 3 | BC42: =IF(BD42="","",RANK(BD42,#REF!)) | BD42: =IF(BE42="","",(COUNTIF($AX$40:BE42,BE42)-1)*0.0001+BE42) | BG42: 5 | BH42: 0.71
B43: 4 | F43: =IF(G43="","",RANK(G43,$G$40:$G$87)) -> 20 | G43: =IF(H43="","",(COUNTIF($H$40:H43,H43)-1)*0.0001+H43) -> 25.85 | H43: 25.85 | J43: 4 | N43: =IF(O43="","",RANK(O43,$O$40:$O$87)) -> 12 | O43: =IF(P43="","",(COUNTIF($P$40:P43,P43)-1)*0.0001+P43) -> 0.39 | P43: 0.39 | R43: 4 | V43: =IF(W43="","",RANK(W43,$W$40:$W$87)) -> 6 | W43: =IF(X43="","",(COUNTIF($X$40:X43,X43)-1)*0.0001+X43) -> 4.29 | X43: 4.29 | Z43: 4 | AD43: =IF(AE43="","",RANK(AE43,$AE$40:$AE$87)) -> 13 | AE43: =IF(AF43="","",(COUNTIF($AF$40:AF43,AF43)-1)*0.0001+AF43) -> 30.4 | AF43: 30.4 | AH43: 4 | AL43: =IF(AM43="","",RANK(AM43,$AM$40:$AM$87)) -> 26 | AM43: =IF(AN43="","",(COUNTIF($AN$40:AN43,AN43)-1)*0.0001+AN43) -> 14 | AN43: 14 | AP43: 4 | AT43: =IF(AU43="","",RANK(AU43,$AU$40:$AU$87)) -> 24 | AU43: =IF(AV43="","",(COUNTIF($AV$40:AV43,AV43)-1)*0.0001+AV43) -> 13.3 | AV43: 13.3 | AY43: 4 | BC43: =IF(BD43="","",RANK(BD43,#REF!)) | BD43: =IF(BE43="","",(COUNTIF($AX$40:BE43,BE43)-1)*0.0001+BE43) | BG43: 6 | BH43: 0.628
B44: 5 | F44: =IF(G44="","",RANK(G44,$G$40:$G$87)) -> 24 | G44: =IF(H44="","",(COUNTIF($H$40:H44,H44)-1)*0.0001+H44) -> 25.64 | H44: 25.64 | J44: 5 | N44: =IF(O44="","",RANK(O44,$O$40:$O$87)) -> 9 | O44: =IF(P44="","",(COUNTIF($P$40:P44,P44)-1)*0.0001+P44) -> 0.4 | P44: 0.4 | R44: 5 | V44: =IF(W44="","",RANK(W44,$W$40:$W$87)) -> 4 | W44: =IF(X44="","",(COUNTIF($X$40:X44,X44)-1)*0.0001+X44) -> 4.3001 | X44: 4.3 | Z44: 5 | AD44: =IF(AE44="","",RANK(AE44,$AE$40:$AE$87)) -> 21 | AE44: =IF(AF44="","",(COUNTIF($AF$40:AF44,AF44)-1)*0.0001+AF44) -> 30.2 | AF44: 30.2 | AH44: 5 | AL44: =IF(AM44="","",RANK(AM44,$AM$40:$AM$87)) -> 24 | AM44: =IF(AN44="","",(COUNTIF($AN$40:AN44,AN44)-1)*0.0001+AN44) -> 14.1 | AN44: 14.1 | AP44: 5 | AT44: =IF(AU44="","",RANK(AU44,$AU$40:$AU$87)) -> 23 | AU44: =IF(AV44="","",(COUNTIF($AV$40:AV44,AV44)-1)*0.0001+AV44) -> 13.3001 | AV44: 13.3 | AY44: 5 | BC44: =IF(BD44="","",RANK(BD44,#REF!)) | BD44: =IF(BE44="","",(COUNTIF($AX$40:BE44,BE44)-1)*0.0001+BE44) | BG44: 7 | BH44: 0.569
B45: 6 | F45: =IF(G45="","",RANK(G45,$G$40:$G$87)) -> 10 | G45: =IF(H45="","",(COUNTIF($H$40:H45,H45)-1)*0.0001+H45) -> 25.97 | H45: 25.97 | J45: 6 | N45: =IF(O45="","",RANK(O45,$O$40:$O$87)) -> 11 | O45: =IF(P45="","",(COUNTIF($P$40:P45,P45)-1)*0.0001+P45) -> 0.3901 | P45: 0.39 | R45: 6 | V45: =IF(W45="","",RANK(W45,$W$40:$W$87)) -> 13 | W45: =IF(X45="","",(COUNTIF($X$40:X45,X45)-1)*0.0001+X45) -> 4.2 | X45: 4.2 | Z45: 6 | AD45: =IF(AE45="","",RANK(AE45,$AE$40:$AE$87)) -> 3 | AE45: =IF(AF45="","",(COUNTIF($AF$40:AF45,AF45)-1)*0.0001+AF45) -> 30.8 | AF45: 30.8 | AH45: 6 | AL45: =IF(AM45="","",RANK(AM45,$AM$40:$AM$87)) -> 8 | AM45: =IF(AN45="","",(COUNTIF($AN$40:AN45,AN45)-1)*0.0001+AN45) -> 14.23 | AN45: 14.23 | AP45: 6 | AT45: =IF(AU45="","",RANK(AU45,$AU$40:$AU$87)) -> 15 | AU45: =IF(AV45="","",(COUNTIF($AV$40:AV45,AV45)-1)*0.0001+AV45) -> 13.6 | AV45: 13.6 | AY45: 6 | BC45: =IF(BD45="","",RANK(BD45,#REF!)) | BD45: =IF(BE45="","",(COUNTIF($AX$40:BE45,BE45)-1)*0.0001+BE45) | BG45: 8 | BH45: 0.608
...

Sheet CV Chart - Low
B2: CONTROL CHART | L2: ='Plot Data'!C7 -> Calorific Value (MJ/kg) | AC2: Control Sample No :
L4: Period / / to / / | AD4: Bomb/Vessel :
B6: Date
B7: Analyst
B8: x1
B9: x2
B10: (x1+x2)/2=X
B11: Ix1-x2I=R
B12: X
C13: ='Plot Data'!Q64 -> 23.45 | AT13: +3s
C15: =C19+(C13-C19)/2 -> 23.4
C19: ='Plot Data'!Q62 -> 23.35 | AT19: +2s
C21: =C25+(C19-C25)/2 -> 23.3
C25: ='Plot Data'!Q63 -> 23.25
C27: =C31+(C25-C31)/2 -> 23.2
C31: ='Plot Data'!Q58 -> 23.15 | AT31: 
C33: =C37+(C31-C37)/2 -> 23.1
C37: ='Plot Data'!Q66 -> 23.05
C39: =C43+(C37-C43)/2 -> 23
C43: ='Plot Data'!Q65 -> 22.95 | AT43: -2s
C45: =C49+(C43-C49)/2 -> 22.9
C49: ='Plot Data'!Q67 -> 22.85 | AT49: -3s
B52: Range
C55: ='Plot Data'!C68 -> 0.12
C59: =C63+(C55-C63)/2 -> 0.105
C63: =C69+(C55-C69)/2 -> 0.09
C69: =C55/2 -> 0.06
C77: =C69/2 -> 0.03
C81: =C77/2 -> 0.015
E85: 1 | G85: 2 | I85: 3 | K85: 4 | M85: 5 | O85: 6 | Q85: 7 | S85: 8 | U85: 9 | W85: 10 | Y85: 11 | AA85: 12 | AC85: 13 | AE85: 14 | AG85: 15 | AI85: 16 | AK85: 17 | AM85: 18 | AO85: 19 | AQ85: 20 | AS85: 21
B86: Assigned Value (Average) =  | H86: Repeatability Range = R | AB86: KEY: | AD86: Control Value | AJ86: Warning Limit | AP86: Action Limit

Sheet Plot Data
B2: Control Chart Construction
C6: Data is automatically imported from "Data Input" Tab provided that all criteria are met
B7: Test Number | C7: Calorific Value (MJ/kg) | D7: Low Total Sulphur (%) | E7: MIAS % | F7: Volatile Matter % | G7: ISO Ash (%) | H7: Quick Ash (%) | I7: High Total Sulphur (%) | J7: AFT Cu Wire (˚C) | K7: AFT Ni (˚C) | L7: AFT QC (˚C) | P7: Calorific Value (MJ/kg) | Q7: Calorific Value (MJ/kg)
B8: 1 | C8: 23.64 | D8: 0.45 | E8: 3.5 | F8: 28.95 | G8: 13.6 | H8: 22.18 | I8: =IF('Data Input'!#REF!="","",IF(AND('Data Input'!#REF!="No",'Data Input'!#REF!="Pass",'Data Input'!#REF!="PASS",'Data Input'!#REF!="PASS"),'Data Input'!#REF!,"")) -> #REF! | J8: 1082 | K8: 1445 | L8: 1260 | M8: 1290 | N8: 1310 | O8: 1360 | P8: 26.432 | Q8: 23.15 | R8: 30.3 | S8: =R8-E8 -> 26.8
B9: 2 | C9: 23.74 | D9: 0.43 | E9: 3.85 | F9: 28.67 | G9: 13.9 | H9: 22.15 | I9: =IF('Data Input'!#REF!="","",IF(AND('Data Input'!#REF!="No",'Data Input'!#REF!="Pass",'Data Input'!#REF!="PASS",'Data Input'!#REF!="PASS"),'Data Input'!#REF!,"")) -> #REF! | J9: 28.95 | K9: 1447 | P9: 26.432 | Q9: 23.15 | R9: 30.45 | S9: =R9-E9 -> 26.6
B10: 3 | C10: 23.71 | D10: 0.43 | E10: 3.6 | F10: 28.67 | G10: 13.4 | H10: 22.14 | I10: =IF('Data Input'!#REF!="","",IF(AND('Data Input'!#REF!="No",'Data Input'!#REF!="Pass",'Data Input'!#REF!="PASS",'Data Input'!#REF!="PASS"),'Data Input'!#REF!,"")) -> #REF! | J10: 29.01 | K10: 1457 | P10: 26.432 | Q10: 23.15 | R10: 30.6 | S10: =R10-E10 -> 27
B11: 4 | C11: 23.71 | D11: 0.41 | E11: 3.6 | F11: 28.71 | G11: 14 | H11: 22.21 | I11: =IF('Data Input'!#REF!="","",IF(AND('Data Input'!#REF!="No",'Data Input'!#REF!="Pass",'Data Input'!#REF!="PASS",'Data Input'!#REF!="PASS"),'Data Input'!#REF!,"")) -> #REF! | J11: 29.09 | K11: 1448 | P11: 26.432 | Q11: 23.15 | R11: 30.4 | S11: =R11-E11 -> 26.8
B12: 5 | C12: 23.82 | D12: 0.4 | E12: 3.88 | F12: 28.81 | G12: 13.7 | H12: 22.3 | I12: =IF('Data Input'!#REF!="","",IF(AND('Data Input'!#REF!="No",'Data Input'!#REF!="Pass",'Data Input'!#REF!="PASS",'Data Input'!#REF!="PASS"),'Data Input'!#REF!,"")) -> #REF! | J12: 28.95 | K12: 1444 | P12: 26.432 | Q12: 23.15 | R12: 30.2 | S12: =R12-E12 -> 26.32
B13: 6 | C13: 23.66 | D13: 0.42 | E13: 3.88 | F13: 28.71 | G13: 13.6 | H13: 21.99 | I13: =IF('Data Input'!#REF!="","",IF(AND('Data Input'!#REF!="No",'Data Input'!#REF!="Pass",'Data Input'!#REF!="PASS",'Data Input'!#REF!="PASS"),'Data Input'!#REF!,"")) -> #REF! | J13: 29.01 | K13: 1458 | P13: 26.432 | Q13: 23.15 | R13: 30.8 | S13: =R13-E13 -> 26.92
B14: 7 | C14: 23.66 | D14: 0.53 | E14: 3.95 | F14: 28.84 | G14: 13.5 | H14: 22.3 | I14: =IF('Data Input'!#REF!="","",IF(AND('Data Input'!#REF!="No",'Data Input'!#REF!="Pass",'Data Input'!#REF!="PASS",'Data Input'!#REF!="PASS"),'Data Input'!#REF!,"")) -> #REF! | J14: 29.33 | K14: 1456 | P14: 26.432 | Q14: 23.15 | R14: 30.21 | S14: =R14-E14 -> 26.26
B15: 8 | C15: 23.73 | D15: 0.44 | E15: 3.6 | F15: 28.71 | G15: 13.4 | H15: 22.43 | I15: =IF('Data Input'!#REF!="","",IF(AND('Data Input'!#REF!="No",'Data Input'!#REF!="Pass",'Data Input'!#REF!="PASS",'Data Input'!#REF!="PASS"),'Data Input'!#REF!,"")) -> #REF! | J15: 29.01 | K15: 1452 | P15: 26.432 | Q15: 23.15 | R15: 30.3 | S15: =R15-E15 -> 26.7
B16: 9 | C16: 23.84 | D16: 0.53 | E16: 3.89 | F16: 28.88 | G16: 13.7 | H16: 22.28 | I16: =IF('Data Input'!#REF!="","",IF(AND('Data Input'!#REF!="No",'Data Input'!#REF!="Pass",'Data Input'!#REF!="PASS",'Data Input'!#REF!="PASS"),'Data Input'!#REF!,"")) -> #REF! | J16: 28.91 | K16: 1447 | P16: 26.432 | Q16: 23.15 | R16: 30.7 | S16: =R16-E16 -> 26.81
B17: 10 | C17: 23.7 | D17: 0.43 | E17: 3.8 | F17: 28.9 | G17: 13.6 | H17: 22.17 | I17: =IF('Data Input'!#REF!="","",IF(AND('Data Input'!#REF!="No",'Data Input'!#REF!="Pass",'Data Input'!#REF!="PASS",'Data Input'!#REF!="PASS"),'Data Input'!#REF!,"")) -> #REF! | J17: 28.91 | K17: 1449 | P17: 26.432 | Q17: 23.15 | R17: 30.6 | S17: =R17-E17 -> 26.8
B18: 11 | C18: 23.7 | D18: 0.4 | E18: 3.6 | F18: 28.84 | G18: 13.2 | H18: 22.47 | I18: =IF('Data Input'!#REF!="","",IF(AND('Data Input'!#REF!="No",'Data Input'!#REF!="Pass",'Data Input'!#REF!="PASS",'Data Input'!#REF!="PASS"),'Data Input'!#REF!,"")) -> #REF! | J18: 28.94 | K18: 1459 | P18: 26.432 | Q18: 23.15 | R18: 30.5 | S18: =R18-E18 -> 26.9
B19: 12 | C19: 23.64 | D19: 0.52 | E19: 3.6 | F19: 28.76 | G19: 13.2 | H19: 22.23 | I19: =IF('Data Input'!#REF!="","",IF(AND('Data Input'!#REF!="No",'Data Input'!#REF!="Pass",'Data Input'!#REF!="PASS",'Data Input'!#REF!="PASS"),'Data Input'!#REF!,"")) -> #REF! | K19: 1455 | P19: 26.432 | Q19: 23.15 | R19: 30.3 | S19: =R19-E19 -> 26.7
B20: 13 | C20: 23.55 | D20: 0.46 | E20: 3.89 | F20: 28.73 | G20: 13.5 | H20: 22.03 | I20: =IF('Data Input'!#REF!="","",IF(AND('Data Input'!#REF!="No",'Data Input'!#REF!="Pass",'Data Input'!#REF!="PASS",'Data Input'!#REF!="PASS"),'Data Input'!#REF!,"")) -> #REF! | K20: 1458 | P20: 26.432 | Q20: 23.15 | R20: 30.3 | S20: =R20-E20 -> 26.41
B21: 14 | C21: 23.59 | D21: 0.47 | E21: 3.6 | F21: 28.72 | G21: 14.2 | H21: 22.34 | I21: =IF('Data Input'!#REF!="","",IF(AND('Data Input'!#REF!="No",'Data Input'!#REF!="Pass",'Data Input'!#REF!="PASS",'Data Input'!#REF!="PASS"),'Data Input'!#REF!,"")) -> #REF! | K21: 1456 | P21: 26.432 | Q21: 23.15 | R21: 30.6 | S21: =R21-E21 -> 27
B22: 15 | C22: 23.77 | D22: 0.5 | E22: 3.6 | F22: 28.82 | G22: 14.3 | H22: 21.77 | I22: =IF('Data Input'!#REF!="","",IF(AND('Data Input'!#REF!="No",'Data Input'!#REF!="Pass",'Data Input'!#REF!="PASS",'Data Input'!#REF!="PASS"),'Data Input'!#REF!,"")) -> #REF! | K22: 1460 | P22: 26.432 | Q22: 23.15 | R22: 30.6 | S22: =R22-E22 -> 27
B23: 16 | C23: 23.93 | D23: 0.51 | E23: 3.6 | F23: 28.77 | G23: 14.4 | H23: 22.1 | I23: =IF('Data Input'!#REF!="","",IF(AND('Data Input'!#REF!="No",'Data Input'!#REF!="Pass",'Data Input'!#REF!="PASS",'Data Input'!#REF!="PASS"),'Data Input'!#REF!,"")) -> #REF! | K23: 1460 | P23: 26.432 | Q23: 23.15 | R23: 30 | S23: =R23-E23 -> 26.4
B24: 17 | C24: 23.91 | D24: 0.43 | E24: 3.84 | F24: 28.56 | G24: 14.3 | H24: 22.03 | I24: =IF('Data Input'!#REF!="","",IF(AND('Data Input'!#REF!="No",'Data Input'!#REF!="Pass",'Data Input'!#REF!="PASS",'Data Input'!#REF!="PASS"),'Data Input'!#REF!,"")) -> #REF! | K24: 1458 | P24: 26.432 | Q24: 23.15 | R24: 30.7 | S24: =R24-E24 -> 26.86
B25: 18 | C25: 23.88 | D25: 0.46 | E25: 3.6 | F25: 28.69 | G25: 14.3 | H25: 22.31 | I25: =IF('Data Input'!#REF!="","",IF(AND('Data Input'!#REF!="No",'Data Input'!#REF!="Pass",'Data Input'!#REF!="PASS",'Data Input'!#REF!="PASS"),'Data Input'!#REF!,"")) -> #REF! | K25: 1456 | P25: 26.432 | Q25: 23.15 | R25: 30.9 | S25: =R25-E25 -> 27.3
B26: 19 | C26: 23.81 | D26: 0.47 | E26: 3.6 | F26: 28.35 | G26: 13.9 | H26: 22.27 | I26: =IF('Data Input'!#REF!="","",IF(AND('Data Input'!#REF!="No",'Data Input'!#REF!="Pass",'Data Input'!#REF!="PASS",'Data Input'!#REF!="PASS"),'Data Input'!#REF!,"")) -> #REF! | K26: 1452 | P26: 26.432 | Q26: 23.15 | R26: 30.8 | S26: =R26-E26 -> 27.2
B27: 20 | C27: 23.86 | D27: 0.49 | E27: 3.6 | F27: 28.35 | G27: 14.1 | H27: 22.28 | I27: =IF('Data Input'!#REF!="","",IF(AND('Data Input'!#REF!="No",'Data Input'!#REF!="Pass",'Data Input'!#REF!="PASS",'Data Input'!#REF!="PASS"),'Data Input'!#REF!,"")) -> #REF! | K27: 1456 | P27: 26.432 | Q27: 23.15 | R27: 30.1 | S27: =R27-E27 -> 26.5
B28: 21 | C28: 23.83 | D28: 0.45 | E28: 3.6 | F28: 28.2 | G28: 14.2 | H28: 21.98 | P28: =IF('Data Input'!U58="","",IF(AND('Data Input'!$F$31="No",'Data Input'!$F$35="PASS",'Data Input'!$F$24="PASS",'Data Input'!$F$26="PASS"),'Data Input'!U58,"")) | Q28: =IF('Data Input'!V58="","",IF(AND('Data Input'!$F$31="No",'Data Input'!$F$35="PASS",'Data Input'!$F$24="PASS",'Data Input'!$F$26="PASS"),'Data Input'!V58,"")) | R28: 30.1 | S28: =R28-E28 -> 26.5
B29: 22 | C29: 23.85 | D29: 0.52 | E29: 3.5 | G29: 14.2 | P29: =IF('Data Input'!U59="","",IF(AND('Data Input'!$F$31="No",'Data Input'!$F$35="PASS",'Data Input'!$F$24="PASS",'Data Input'!$F$26="PASS"),'Data Input'!U59,"")) | Q29: =IF('Data Input'!V59="","",IF(AND('Data Input'!$F$31="No",'Data Input'!$F$35="PASS",'Data Input'!$F$24="PASS",'Data Input'!$F$26="PASS"),'Data Input'!V59,"")) | R29: 30 | S29: =R29-E29 -> 26.5
B30: 23 | D30: 0.46 | E30: 3.5 | G30: 14.1 | P30: =IF('Data Input'!U60="","",IF(AND('Data Input'!$F$31="No",'Data Input'!$F$35="PASS",'Data Input'!$F$24="PASS",'Data Input'!$F$26="PASS"),'Data Input'!U60,"")) | Q30: =IF('Data Input'!V60="","",IF(AND('Data Input'!$F$31="No",'Data Input'!$F$35="PASS",'Data Input'!$F$24="PASS",'Data Input'!$F$26="PASS"),'Data Input'!V60,"")) | R30: 30.2 | S30: =R30-E30 -> 26.7
B31: 24 | D31: 0.46 | E31: 3.5 | G31: 14.1 | P31: =IF('Data Input'!U61="","",IF(AND('Data Input'!$F$31="No",'Data Input'!$F$35="PASS",'Data Input'!$F$24="PASS",'Data Input'!$F$26="PASS"),'Data Input'!U61,"")) | Q31: =IF('Data Input'!V61="","",IF(AND('Data Input'!$F$31="No",'Data Input'!$F$35="PASS",'Data Input'!$F$24="PASS",'Data Input'!$F$26="PASS"),'Data Input'!V61,"")) | R31: 30.23 | S31: =R31-E31 -> 26.73
B32: 25 | D32: 0.47 | E32: 3.5 | G32: 14.1 | P32: =IF('Data Input'!U62="","",IF(AND('Data Input'!$F$31="No",'Data Input'!$F$35="PASS",'Data Input'!$F$24="PASS",'Data Input'!$F$26="PASS"),'Data Input'!U62,"")) | Q32: =IF('Data Input'!V62="","",IF(AND('Data Input'!$F$31="No",'Data Input'!$F$35="PASS",'Data Input'!$F$24="PASS",'Data Input'!$F$26="PASS"),'Data Input'!V62,"")) | R32: 30.6 | S32: =R32-E32 -> 27.1
B33: 26 | D33: 0.41 | E33: 3.5 | G33: 14 | P33: =IF('Data Input'!U63="","",IF(AND('Data Input'!$F$31="No",'Data Input'!$F$35="PASS",'Data Input'!$F$24="PASS",'Data Input'!$F$26="PASS"),'Data Input'!U63,"")) | Q33: =IF('Data Input'!V63="","",IF(AND('Data Input'!$F$31="No",'Data Input'!$F$35="PASS",'Data Input'!$F$24="PASS",'Data Input'!$F$26="PASS"),'Data Input'!V63,"")) | R33: 30.1 | S33: =R33-E33 -> 26.6
B34: 27 | P34: =IF('Data Input'!U64="","",IF(AND('Data Input'!$F$31="No",'Data Input'!$F$35="PASS",'Data Input'!$F$24="PASS",'Data Input'!$F$26="PASS"),'Data Input'!U64,"")) | Q34: =IF('Data Input'!V64="","",IF(AND('Data Input'!$F$31="No",'Data Input'!$F$35="PASS",'Data Input'!$F$24="PASS",'Data Input'!$F$26="PASS"),'Data Input'!V64,""))
B35: 28 | P35: =IF('Data Input'!U65="","",IF(AND('Data Input'!$F$31="No",'Data Input'!$F$35="PASS",'Data Input'!$F$24="PASS",'Data Input'!$F$26="PASS"),'Data Input'!U65,"")) | Q35: =IF('Data Input'!V65="","",IF(AND('Data Input'!$F$31="No",'Data Input'!$F$35="PASS",'Data Input'!$F$24="PASS",'Data Input'!$F$26="PASS"),'Data Input'!V65,""))
B36: 29 | P36: =IF('Data Input'!U66="","",IF(AND('Data Input'!$F$31="No",'Data Input'!$F$35="PASS",'Data Input'!$F$24="PASS",'Data Input'!$F$26="PASS"),'Data Input'!U66,"")) | Q36: =IF('Data Input'!V66="","",IF(AND('Data Input'!$F$31="No",'Data Input'!$F$35="PASS",'Data Input'!$F$24="PASS",'Data Input'!$F$26="PASS"),'Data Input'!V66,""))
B37: 30 | P37: =IF('Data Input'!U67="","",IF(AND('Data Input'!$F$31="No",'Data Input'!$F$35="PASS",'Data Input'!$F$24="PASS",'Data Input'!$F$26="PASS"),'Data Input'!U67,"")) | Q37: =IF('Data Input'!V67="","",IF(AND('Data Input'!$F$31="No",'Data Input'!$F$35="PASS",'Data Input'!$F$24="PASS",'Data Input'!$F$26="PASS"),'Data Input'!V67,""))
B38: 31 | I38: =IF('Data Input'!AW68="","",IF(AND('Data Input'!$AT$31="No",'Data Input'!$AT$35="Pass",'Data Input'!$AT$24="PASS",'Data Input'!$AT$26="PASS"),'Data Input'!AW68,"")) | P38: =IF('Data Input'!U68="","",IF(AND('Data Input'!$F$31="No",'Data Input'!$F$35="PASS",'Data Input'!$F$24="PASS",'Data Input'!$F$26="PASS"),'Data Input'!U68,"")) | Q38: =IF('Data Input'!V68="","",IF(AND('Data Input'!$F$31="No",'Data Input'!$F$35="PASS",'Data Input'!$F$24="PASS",'Data Input'!$F$26="PASS"),'Data Input'!V68,""))
B39: 32 | P39: =IF('Data Input'!U69="","",IF(AND('Data Input'!$F$31="No",'Data Input'!$F$35="PASS",'Data Input'!$F$24="PASS",'Data Input'!$F$26="PASS"),'Data Input'!U69,"")) | Q39: =IF('Data Input'!V69="","",IF(AND('Data Input'!$F$31="No",'Data Input'!$F$35="PASS",'Data Input'!$F$24="PASS",'Data Input'!$F$26="PASS"),'Data Input'!V69,""))
B40: 33 | P40: =IF('Data Input'!U70="","",IF(AND('Data Input'!$F$31="No",'Data Input'!$F$35="PASS",'Data Input'!$F$24="PASS",'Data Input'!$F$26="PASS"),'Data Input'!U70,"")) | Q40: =IF('Data Input'!V70="","",IF(AND('Data Input'!$F$31="No",'Data Input'!$F$35="PASS",'Data Input'!$F$24="PASS",'Data Input'!$F$26="PASS"),'Data Input'!V70,""))
B41: 34 | P41: =IF('Data Input'!U71="","",IF(AND('Data Input'!$F$31="No",'Data Input'!$F$35="PASS",'Data Input'!$F$24="PASS",'Data Input'!$F$26="PASS"),'Data Input'!U71,"")) | Q41: =IF('Data Input'!V71="","",IF(AND('Data Input'!$F$31="No",'Data Input'!$F$35="PASS",'Data Input'!$F$24="PASS",'Data Input'!$F$26="PASS"),'Data Input'!V71,""))
B42: 35 | P42: =IF('Data Input'!U72="","",IF(AND('Data Input'!$F$31="No",'Data Input'!$F$35="PASS",'Data Input'!$F$24="PASS",'Data Input'!$F$26="PASS"),'Data Input'!U72,"")) | Q42: =IF('Data Input'!V72="","",IF(AND('Data Input'!$F$31="No",'Data Input'!$F$35="PASS",'Data Input'!$F$24="PASS",'Data Input'!$F$26="PASS"),'Data Input'!V72,""))
B43: 36 | P43: =IF('Data Input'!U73="","",IF(AND('Data Input'!$F$31="No",'Data Input'!$F$35="PASS",'Data Input'!$F$24="PASS",'Data Input'!$F$26="PASS"),'Data Input'!U73,"")) | Q43: =IF('Data Input'!V73="","",IF(AND('Data Input'!$F$31="No",'Data Input'!$F$35="PASS",'Data Input'!$F$24="PASS",'Data Input'!$F$26="PASS"),'Data Input'!V73,""))
B44: 37 | P44: =IF('Data Input'!U74="","",IF(AND('Data Input'!$F$31="No",'Data Input'!$F$35="PASS",'Data Input'!$F$24="PASS",'Data Input'!$F$26="PASS"),'Data Input'!U74,"")) | Q44: =IF('Data Input'!V74="","",IF(AND('Data Input'!$F$31="No",'Data Input'!$F$35="PASS",'Data Input'!$F$24="PASS",'Data Input'!$F$26="PASS"),'Data Input'!V74,""))
...

Sheet CV Chart
B2: CONTROL CHART | L2: ='Plot Data'!C7 -> Calorific Value (MJ/kg) | AC2: Control Sample No : | AK2: ='Data Input'!F11 -> AS CRM 002
L4: Period / / to / / | AD4: Bomb/Vessel :
B6: Date
B7: Analyst
B8: x1
B9: x2
B10: (x1+x2)/2=X
B11: Ix1-x2I=R
B12: X
C13: ='Plot Data'!C64 -> 24.068759 | AT13: +3s
C15: =C19+(C13-C19)/2 -> 24.01586
C19: ='Plot Data'!C62 -> 23.96296 | AT19: +2s
C21: =C25+(C19-C25)/2 -> 23.910061
C25: ='Plot Data'!C63 -> 23.857162
C27: =C31+(C25-C31)/2 -> 23.804263
C31: ='Plot Data'!C58 -> 23.751364 | AT31: 
C33: =C37+(C31-C37)/2 -> 23.698464
C37: ='Plot Data'!C66 -> 23.645565
C39: =C43+(C37-C43)/2 -> 23.592666
C43: ='Plot Data'!C65 -> 23.539767 | AT43: -2s
C45: =C49+(C43-C49)/2 -> 23.486868
C49: ='Plot Data'!C67 -> 23.433969 | AT49: -3s
B52: Range
C55: ='Plot Data'!C68 -> 0.12
C59: =C63+(C55-C63)/2 -> 0.105
C63: =C69+(C55-C69)/2 -> 0.09
C69: =C55/2 -> 0.06
C77: =C69/2 -> 0.03
C81: =C77/2 -> 0.015
E85: 1 | G85: 2 | I85: 3 | K85: 4 | M85: 5 | O85: 6 | Q85: 7 | S85: 8 | U85: 9 | W85: 10 | Y85: 11 | AA85: 12 | AC85: 13 | AE85: 14 | AG85: 15 | AI85: 16 | AK85: 17 | AM85: 18 | AO85: 19 | AQ85: 20 | AS85: 21
B86: Assigned Value (Average) =  | H86: Repeatability Range = R | AB86: KEY: | AD86: Control Value | AJ86: Warning Limit | AP86: Action Limit

Sheet CV Chart - Benzoic
B2: CONTROL CHART | L2: ='Plot Data'!C7 -> Calorific Value (MJ/kg) | AC2: Control Sample No : | AK2: ='Data Input'!BC11 -> Benzoic Acid
L4: Period / / to / / | AD4: Bomb/Vessel : | AK4: 2
B6: Date
B7: Analyst
B8: x1
B9: x2
B10: (x1+x2)/2=X
B11: Ix1-x2I=R
B12: X
C13: ='Plot Data'!P64 -> 26.552 | AT13: +3s
C15: =C19+(C13-C19)/2 -> 26.532
C19: ='Plot Data'!P62 -> 26.512 | AT19: +2s
C21: =C25+(C19-C25)/2 -> 26.492
C25: ='Plot Data'!P63 -> 26.472
C27: =C31+(C25-C31)/2 -> 26.452
C31: ='Plot Data'!P58 -> 26.432 | AT31: 
C33: =C37+(C31-C37)/2 -> 26.412
C37: ='Plot Data'!P66 -> 26.392
C39: =C43+(C37-C43)/2 -> 26.372
C43: ='Plot Data'!P65 -> 26.352 | AT43: -2s
C45: =C49+(C43-C49)/2 -> 26.332
C49: ='Plot Data'!P67 -> 26.312 | AT49: -3s
B52: Range
C55: ='Plot Data'!C68 -> 0.12
C59: =C63+(C55-C63)/2 -> 0.105
C63: =C69+(C55-C69)/2 -> 0.09
C69: =C55/2 -> 0.06
C77: =C69/2 -> 0.03
C81: =C77/2 -> 0.015
E85: 1 | G85: 2 | I85: 3 | K85: 4 | M85: 5 | O85: 6 | Q85: 7 | S85: 8 | U85: 9 | W85: 10 | Y85: 11 | AA85: 12 | AC85: 13 | AE85: 14 | AG85: 15 | AI85: 16 | AK85: 17 | AM85: 18 | AO85: 19 | AQ85: 20 | AS85: 21
B86: Assigned Value (Average) =  | H86: Repeatability Range = R | AB86: KEY: | AD86: Control Value | AJ86: Warning Limit | AP86: Action Limit

Sheet TS Chart Low
B2: CONTROL CHART | L2: ='Plot Data'!D7 -> Low Total Sulphur (%) | AC2: Control Sample No : | AK2: ='Data Input'!N11 -> AS CRM 002
L4: Period / / to / / | AD4: Instrument No :
B6: Date
B7: Analyst
B8: x1
B9: x2
B10: (x1+x2)/2=X
B11: Ix1-x2I=R
B12: X
C13: ='Plot Data'!D64 -> 0.58044341 | AT13: +3s
C15: =C19+(C13-C19)/2 -> 0.56036951
C19: ='Plot Data'!D62 -> 0.54029561 | AT19: +2s
C21: =C25+(C19-C25)/2 -> 0.52022171
C25: ='Plot Data'!D63 -> 0.5001478
C27: =C31+(C25-C31)/2 -> 0.4800739
C31: ='Plot Data'!D58 -> 0.46 | AT31: 
C33: =C37+(C31-C37)/2 -> 0.4399261
C37: ='Plot Data'!D66 -> 0.4198522
C39: =C43+(C37-C43)/2 -> 0.39977829
C43: ='Plot Data'!D65 -> 0.37970439 | AT43: -2s
C45: =C49+(C43-C49)/2 -> 0.35963049
C49: ='Plot Data'!D67 -> 0.33955659 | AT49: -3s
B52: Range
C55: ='Plot Data'!D68 -> 0.0338
C59: =C63+(C55-C63)/2 -> 0.029575
C63: =C69+(C55-C69)/2 -> 0.02535
C69: =C55/2 -> 0.0169
C77: =C69/2 -> 0.00845
C81: =C77/2 -> 0.004225
E85: 1 | G85: 2 | I85: 3 | K85: 4 | M85: 5 | O85: 6 | Q85: 7 | S85: 8 | U85: 9 | W85: 10 | Y85: 11 | AA85: 12 | AC85: 13 | AE85: 14 | AG85: 15 | AI85: 16 | AK85: 17 | AM85: 18 | AO85: 19 | AQ85: 20 | AS85: 21
B86: Assigned Value (Average) =  | H86: Repeatability Range = R | AB86: KEY: | AD86: Control Value | AJ86: Warning Limit | AP86: Action Limit

Sheet TS Chart High
B2: CONTROL CHART | L2: ='Plot Data'!I7 -> High Total Sulphur (%) | AC2: Control Sample No : | AK2: ='Data Input'!#REF! -> #REF!
L4: Period / / to / / | AD4: Instrument No :
B6: Date
B7: Analyst
B8: x1
B9: x2
B10: (x1+x2)/2=X
B11: Ix1-x2I=R
B12: X
C13: ='Plot Data'!I64 -> #REF! | AT13: +3s
C15: =C19+(C13-C19)/2 -> #REF!
C19: ='Plot Data'!I62 -> #REF! | AT19: +2s
C21: =C25+(C19-C25)/2 -> #REF!
C25: ='Plot Data'!I63 -> #REF!
C27: =C31+(C25-C31)/2 -> #REF!
C31: ='Plot Data'!I58 -> #REF! | AT31: 
C33: =C37+(C31-C37)/2 -> #REF!
C37: ='Plot Data'!I66 -> #REF!
C39: =C43+(C37-C43)/2 -> #REF!
C43: ='Plot Data'!I65 -> #REF! | AT43: -2s
C45: =C49+(C43-C49)/2 -> #REF!
C49: ='Plot Data'!I67 -> #REF! | AT49: -3s
B52: Range
C55: ='Plot Data'!I68 -> #REF!
C59: =C63+(C55-C63)/2 -> #REF!
C63: =C69+(C55-C69)/2 -> #REF!
C69: =C55/2 -> #REF!
C77: =C69/2 -> #REF!
C81: =C77/2 -> #REF!
E85: 1 | G85: 2 | I85: 3 | K85: 4 | M85: 5 | O85: 6 | Q85: 7 | S85: 8 | U85: 9 | W85: 10 | Y85: 11 | AA85: 12 | AC85: 13 | AE85: 14 | AG85: 15 | AI85: 16 | AK85: 17 | AM85: 18 | AO85: 19 | AQ85: 20 | AS85: 21
B86: Assigned Value (Average) =  | H86: Repeatability Range = R | AB86: KEY: | AD86: Control Value | AJ86: Warning Limit | AP86: Action Limit

Sheet MIAS Chart
B2: CONTROL CHART | L2: ='Plot Data'!E7 -> MIAS % | AC2: Control Sample No : | AK2: ='Data Input'!V11 -> AS CRM 002
L4: Period / / to / / | AD4: Oven No :
B6: Date
B7: Analyst
B8: x1
B9: x2
B10: (x1+x2)/2=X
B11: Ix1-x2I=R
B12: X
C13: ='Plot Data'!E64 -> 4.1143885 | AT13: +3s
C15: =C19+(C13-C19)/2 -> 4.0387853
C19: ='Plot Data'!E62 -> 3.9631821 | AT19: +2s
C21: =C25+(C19-C25)/2 -> 3.8875789
C25: ='Plot Data'!E63 -> 3.8119757
C27: =C31+(C25-C31)/2 -> 3.7363724
C31: ='Plot Data'!E58 -> 3.6607692 | AT31: 
C33: =C37+(C31-C37)/2 -> 3.585166
C37: ='Plot Data'!E66 -> 3.5095628
C39: =C43+(C37-C43)/2 -> 3.4339596
C43: ='Plot Data'!E65 -> 3.3583564 | AT43: -2s
C45: =C49+(C43-C49)/2 -> 3.2827532
C49: ='Plot Data'!E67 -> 3.2071499 | AT49: -3s
B52: Range
C55: ='Plot Data'!E68 -> 0.1
C59: =C63+(C55-C63)/2 -> 0.0875
C63: =C69+(C55-C69)/2 -> 0.075
C69: =C55/2 -> 0.05
C77: =C69/2 -> 0.025
C81: =C77/2 -> 0.0125
E85: 1 | G85: 2 | I85: 3 | K85: 4 | M85: 5 | O85: 6 | Q85: 7 | S85: 8 | U85: 9 | W85: 10 | Y85: 11 | AA85: 12 | AC85: 13 | AE85: 14 | AG85: 15 | AI85: 16 | AK85: 17 | AM85: 18 | AO85: 19 | AQ85: 20 | AS85: 21
B86: Assigned Value (Average) =  | H86: Repeatability Range = R | AB86: KEY: | AD86: Control Value | AJ86: Warning Limit | AP86: Action Limit

Sheet VM Chart
B2: CONTROL CHART | L2: ='Plot Data'!F7 -> Volatile Matter % | AC2: Control Sample No : | AK2: ='Data Input'!AD11 -> AS CRM 002
L4: Period / / to / / | AD4: Furnace No :
B6: Date
B7: Analyst
B8: x1
B9: x2
B10: (x1+x2)/2=X
B11: Ix1-x2I=R
B12: X
C13: ='Plot Data'!F64 -> 29.459785 | AT13: +3s
C15: =C19+(C13-C19)/2 -> 29.31679
C19: ='Plot Data'!F62 -> 29.173794 | AT19: +2s
C21: =C25+(C19-C25)/2 -> 29.030799
C25: ='Plot Data'!F63 -> 28.887803
C27: =C31+(C25-C31)/2 -> 28.792473
C31: ='Plot Data'!F58 -> 28.697143 | AT31: 
C33: =C37+(C31-C37)/2 -> 28.601813
C37: ='Plot Data'!F66 -> 28.506482
C39: =C43+(C37-C43)/2 -> 28.363487
C43: ='Plot Data'!F65 -> 28.220492 | AT43: -2s
C45: =C49+(C43-C49)/2 -> 28.077496
C49: ='Plot Data'!F67 -> 27.934501 | AT49: -3s
B52: Range
C55: ='Plot Data'!F68 -> 0.86091429
C59: =C63+(C55-C63)/2 -> 0.7533
C63: =C69+(C55-C69)/2 -> 0.64568571
C69: =C55/2 -> 0.43045714
C77: =C69/2 -> 0.21522857
C81: =C77/2 -> 0.10761429
E85: 1 | G85: 2 | I85: 3 | K85: 4 | M85: 5 | O85: 6 | Q85: 7 | S85: 8 | U85: 9 | W85: 10 | Y85: 11 | AA85: 12 | AC85: 13 | AE85: 14 | AG85: 15 | AI85: 16 | AK85: 17 | AM85: 18 | AO85: 19 | AQ85: 20 | AS85: 21
B86: Assigned Value (Average) =  | H86: Repeatability Range = R | AB86: KEY: | AD86: Control Value | AJ86: Warning Limit | AP86: Action Limit

Sheet ISO Ash Chart
B2: CONTROL CHART | L2: ='Plot Data'!G7 -> ISO Ash (%) | AC2: Control Sample No : | AK2: ='Data Input'!AL11 -> AS CRM 002
L4: Period / / to / / | AD4: Furnace No :
B6: Date
B7: Analyst
B8: x1
B9: x2
B10: (x1+x2)/2=X
B11: Ix1-x2I=R
B12: X
C13: ='Plot Data'!G64 -> 14.955148 | AT13: +3s
C15: =C19+(C13-C19)/2 -> 14.773521
C19: ='Plot Data'!G62 -> 14.591894 | AT19: +2s
C21: =C25+(C19-C25)/2 -> 14.410266
C25: ='Plot Data'!G63 -> 14.228639
C27: =C31+(C25-C31)/2 -> 14.047012
C31: ='Plot Data'!G58 -> 13.865385 | AT31: 
C33: =C37+(C31-C37)/2 -> 13.683757
C37: ='Plot Data'!G66 -> 13.50213
C39: =C43+(C37-C43)/2 -> 13.320503
C43: ='Plot Data'!G65 -> 13.138876 | AT43: -2s
C45: =C49+(C43-C49)/2 -> 12.957248
C49: ='Plot Data'!G67 -> 12.775621 | AT49: -3s
B52: Range
C55: ='Plot Data'!G68 -> 0.27730769
C59: =C63+(C55-C63)/2 -> 0.24264423
C63: =C69+(C55-C69)/2 -> 0.20798077
C69: =C55/2 -> 0.13865385
C77: =C69/2 -> 0.069326923
C81: =C77/2 -> 0.034663462
E85: 1 | G85: 2 | I85: 3 | K85: 4 | M85: 5 | O85: 6 | Q85: 7 | S85: 8 | U85: 9 | W85: 10 | Y85: 11 | AA85: 12 | AC85: 13 | AE85: 14 | AG85: 15 | AI85: 16 | AK85: 17 | AM85: 18 | AO85: 19 | AQ85: 20 | AS85: 21
B86: Assigned Value (Average) =  | H86: Repeatability Range = R | AB86: KEY: | AD86: Control Value | AJ86: Warning Limit | AP86: Action Limit

Sheet Quick Ash Chart
B2: CONTROL CHART | L2: ='Plot Data'!H7 -> Quick Ash (%) | AC2: Control Sample No : | AK2: ='Data Input'!AT11 -> AS CRM 002
L4: Period / / to / / | AD4: Furnace No :
B6: Date
B7: Analyst
B8: x1
B9: x2
B10: (x1+x2)/2=X
B11: Ix1-x2I=R
B12: X
C13: ='Plot Data'!H64 -> 22.684279 | AT13: +3s
C15: =C19+(C13-C19)/2 -> 22.601661
C19: ='Plot Data'!H62 -> 22.519043 | AT19: +2s
C21: =C25+(C19-C25)/2 -> 22.436425
C25: ='Plot Data'!H63 -> 22.353807
C27: =C31+(C25-C31)/2 -> 22.271189
C31: ='Plot Data'!H58 -> 22.188571 | AT31: 
C33: =C37+(C31-C37)/2 -> 22.105954
C37: ='Plot Data'!H66 -> 22.023336
C39: =C43+(C37-C43)/2 -> 21.940718
C43: ='Plot Data'!H65 -> 21.8581 | AT43: -2s
C45: =C49+(C43-C49)/2 -> 21.775482
C49: ='Plot Data'!H67 -> 21.692864 | AT49: -3s
B52: Range
C55: ='Plot Data'!H68 -> 0.44377143
C59: =C63+(C55-C63)/2 -> 0.3883
C63: =C69+(C55-C69)/2 -> 0.33282857
C69: =C55/2 -> 0.22188571
C77: =C69/2 -> 0.11094286
C81: =C77/2 -> 0.055471429
E85: 1 | G85: 2 | I85: 3 | K85: 4 | M85: 5 | O85: 6 | Q85: 7 | S85: 8 | U85: 9 | W85: 10 | Y85: 11 | AA85: 12 | AC85: 13 | AE85: 14 | AG85: 15 | AI85: 16 | AK85: 17 | AM85: 18 | AO85: 19 | AQ85: 20 | AS85: 21
B86: Assigned Value (Average) =  | H86: Repeatability Range = R | AB86: KEY: | AD86: Control Value | AJ86: Warning Limit | AP86: 96

Sheet ACTION SHEET CONTROL CHARTS
B3: ACTIONS FOR CONTROL CHART VIOLATIONS
B5: Date | C5: A | D5: B | E5: C | F5: D | G5: Manager/Supervisor Action

Sheet AFT Cu Chart
B2: CONTROL CHART | L2: ='Plot Data'!J7 -> AFT Cu Wire (˚C) | AC2: Control Sample No : | AK2: Cu Wire
L4: Period / / to / / | AD4: Instrument No :
B6: Date
B7: Analyst
B8: x1
B9: x2
B10: (x1+x2)/2=X
B11: Ix1-x2I=R
B12: X
C13: ='Plot Data'!J64 -> 141.23727 | AT13: +3s
C15: =C19+(C13-C19)/2 -> 138.48727
C19: ='Plot Data'!J62 -> 135.73727 | AT19: +2s
C21: =C25+(C19-C25)/2 -> 132.98727
C25: ='Plot Data'!J63 -> 130.23727
C27: =C31+(C25-C31)/2 -> 127.48727
C31: ='Plot Data'!J58 -> 124.73727 | AT31: 
C33: =C37+(C31-C37)/2 -> 121.98727
C37: ='Plot Data'!J66 -> 119.23727
C39: =C43+(C37-C43)/2 -> 116.48727
C43: ='Plot Data'!J65 -> 113.73727 | AT43: -2s
C45: =C49+(C43-C49)/2 -> 110.98727
C49: ='Plot Data'!J67 -> 108.23727 | AT49: -3s
B52: Range
C55: ='Plot Data'!J68 -> 30
C59: =C63+(C55-C63)/2 -> 26.25
C63: =C69+(C55-C69)/2 -> 22.5
C69: =C55/2 -> 15
C77: =C69/2 -> 7.5
C81: =C77/2 -> 3.75
E85: 1 | G85: 2 | I85: 3 | K85: 4 | M85: 5 | O85: 6 | Q85: 7 | S85: 8 | U85: 9 | W85: 10 | Y85: 11 | AA85: 12 | AC85: 13 | AE85: 14 | AG85: 15 | AI85: 16 | AK85: 17 | AM85: 18 | AO85: 19 | AQ85: 20 | AS85: 21
B86: Assigned Value (Average) =  | H86: Repeatability Range = R | AB86: KEY: | AD86: Control Value | AJ86: Warning Limit | AP86: Action Limit

Sheet AFT Ni Chart
B2: CONTROL CHART | L2: ='Plot Data'!K7 -> AFT Ni (˚C) | AC2: Control Sample No : | AK2: Ni Wire - LECO 501-951
L4: Period / / to / / | AD4: Instrument No :
B6: Date
B7: Analyst
B8: x1
B9: x2
B10: (x1+x2)/2=X
B11: Ix1-x2I=R
B12: X
C13: ='Plot Data'!K64 -> 1469.2923 | AT13: +3s
C15: =C19+(C13-C19)/2 -> 1466.6853
C19: ='Plot Data'!K62 -> 1464.0782 | AT19: +2s
C21: =C25+(C19-C25)/2 -> 1461.4712
C25: ='Plot Data'!K63 -> 1458.8641
C27: =C31+(C25-C31)/2 -> 1456.2571
C31: ='Plot Data'!K58 -> 1453.65 | AT31: 
C33: =C37+(C31-C37)/2 -> 1451.0429
C37: ='Plot Data'!K66 -> 1448.4359
C39: =C43+(C37-C43)/2 -> 1445.8288
C43: ='Plot Data'!K65 -> 1443.2218 | AT43: -2s
C45: =C49+(C43-C49)/2 -> 1440.6147
C49: ='Plot Data'!K67 -> 1438.0077 | AT49: -3s
B52: Range
C55: ='Plot Data'!K68 -> 30
C59: =C63+(C55-C63)/2 -> 26.25
C63: =C69+(C55-C69)/2 -> 22.5
C69: =C55/2 -> 15
C77: =C69/2 -> 7.5
C81: =C77/2 -> 3.75
E85: 1 | G85: 2 | I85: 3 | K85: 4 | M85: 5 | O85: 6 | Q85: 7 | S85: 8 | U85: 9 | W85: 10 | Y85: 11 | AA85: 12 | AC85: 13 | AE85: 14 | AG85: 15 | AI85: 16 | AK85: 17 | AM85: 18 | AO85: 19 | AQ85: 20 | AS85: 21
B86: Assigned Value (Average) =  | H86: Repeatability Range = R | AB86: KEY: | AD86: Control Value | AJ86: Warning Limit | AP86: Action Limit

Sheet AFT QC
B2: CONTROL CHART | L2: ='Plot Data'!L7:O7 -> AFT QC (˚C) | AC2: Control Sample No : | AK2: CC CRM 020
L4: Period / / to / / | AD4: Instrument No :
B6: Date
B7: Analyst
B8: DT
B9: ST
B10: HT
B11: FT
B12: DT
C13: ='Plot Data'!L64 -> 1290 | AT13: +3s
C15: =C19+(C13-C19)/2 -> 1285
C19: ='Plot Data'!L62 -> 1280 | AT19: +2s
C21: =C25+(C19-C25)/2 -> 1275
C25: ='Plot Data'!L63 -> 1270
C27: =C31+(C25-C31)/2 -> 1265
C31: ='Plot Data'!L58 -> 1260 | AT31: 
C33: =C37+(C31-C37)/2 -> 1255
C37: ='Plot Data'!L66 -> 1250
C39: =C43+(C37-C43)/2 -> 1245
C43: ='Plot Data'!L65 -> 1240 | AT43: -2s
C45: =C49+(C43-C49)/2 -> 1235
C49: ='Plot Data'!L67 -> 1230 | AT49: -3s
B52: ST
C53: ='Plot Data'!M64 -> 1320 | AT53: +3s
C55: =C59+(C53-C59)/2 -> 1315
C59: ='Plot Data'!M62 -> 1310 | AT59: +2s
C61: =C65+(C59-C65)/2 -> 1305
C65: ='Plot Data'!M63 -> 1300
C67: =C71+(C65-C71)/2 -> 1295
C71: ='Plot Data'!M58 -> 1290 | AT71: 
C73: =C77+(C71-C77)/2 -> 1285
C77: ='Plot Data'!M66 -> 1280
C79: =C83+(C77-C83)/2 -> 1275
C83: ='Plot Data'!M65 -> 1270 | AT83: -2s
C85: =C89+(C83-C89)/2 -> 1265
C89: ='Plot Data'!M67 -> 1260 | AT89: -3s
B92: HT
C93: ='Plot Data'!N64 -> 1340 | AT93: +3s
C95: =C99+(C93-C99)/2 -> 1335
C99: ='Plot Data'!N62 -> 1330 | AT99: +2s
...

Sheet CV 1
B2: Calorific Value | E2: MJ/kg | H2: Bomb/Vessel | J2: IMP-CAL-01
B3: CRM | E3: 034 | H3: Dates | I3: =C6 -> 37212 | J3: to | K3: =MAX(C6:C55) -> 39038
B5: Point | C5: Date | D5: Name | E5: Duplicate 1 | F5: Duplicate 2 | G5: Average Result | H5: Range (actual) | I5: -3s | J5: -2s | K5:  | L5: +2s | M5: +3s | N5: Range Limit | O5: Rule 1 | P5: Rule 2 | Q5: Rule 3 | R5: Rule 4 | T5: +ve | U5: -ve | AC5: Rule 5 | AD5: Range OK? | AF5: Control Chart | AH5: =B2 -> Calorific Value | AK5: Instrument | AN5: =J2 -> IMP-CAL-01
B6: 1 | C6: 37212 | E6: 27.1 | F6: 27 | G6: =IF(AND(E6="",F6=""),NA(),AVERAGE(E6:F6)) -> 27.05 | H6: =IF(AND(E6="",F6=""),NA(),ABS(E6-F6)) -> 0.1 | I6: ='Plot Data'!$C$67 -> 23.433969 | J6: ='Plot Data'!$C$65 -> 23.539767 | K6: ='Plot Data'!$C$58 -> 23.751364 | L6: ='Plot Data'!$C$62 -> 23.96296 | M6: ='Plot Data'!$C$64 -> 24.068759 | N6: ='Plot Data'!$C$68 -> 0.12 | O6: =IF(G6>M6,">+3s",IF(G6<I6,"<-3s","Pass")) -> >+3s | AD6: =IF(H6="","",IF(H6>N6,"No","Yes")) -> Yes | AF6: CRM | AH6: =E3 -> 034 | AK6: Dates | AN6: =I3 -> 37212 | AO6: to | AP6: =K3 -> 39038
B7: 2 | C7: 37577 | E7: 26.83 | F7: 26.8 | G7: =IF(AND(E7="",F7=""),NA(),AVERAGE(E7:F7)) -> 26.815 | H7: =IF(AND(E7="",F7=""),NA(),ABS(E7-F7)) -> 0.03 | I7: ='Plot Data'!$C$67 -> 23.433969 | J7: ='Plot Data'!$C$65 -> 23.539767 | K7: ='Plot Data'!$C$58 -> 23.751364 | L7: ='Plot Data'!$C$62 -> 23.96296 | M7: ='Plot Data'!$C$64 -> 24.068759 | N7: ='Plot Data'!$C$68 -> 0.12 | O7: =IF(G7>M7,">+3s",IF(G7<I7,"<-3s","Pass")) -> >+3s | P7: =IF(AND(G7>L7,G6>L6),"Fail > +2s",IF(AND(G7<J7,G6<J6),"Fail < -2s","Pass")) -> Fail > +2s | S7: =IF(E7="","",IF(G7>G6,"+",IF(G7<G6,"-",""))) -> - | AD7: =IF(H7="","",IF(H7>N7,"No","Yes")) -> Yes
B8: 3 | C8: 37942 | E8: 26.93 | F8: 27 | G8: =IF(AND(E8="",F8=""),NA(),AVERAGE(E8:F8)) -> 26.965 | H8: =IF(AND(E8="",F8=""),NA(),ABS(E8-F8)) -> 0.07 | I8: ='Plot Data'!$C$67 -> 23.433969 | J8: ='Plot Data'!$C$65 -> 23.539767 | K8: ='Plot Data'!$C$58 -> 23.751364 | L8: ='Plot Data'!$C$62 -> 23.96296 | M8: ='Plot Data'!$C$64 -> 24.068759 | N8: ='Plot Data'!$C$68 -> 0.12 | O8: =IF(G8>M8,">+3s",IF(G8<I8,"<-3s","Pass")) -> >+3s | P8: =IF(AND(G8>L8,G7>L7),"Fail > +2s",IF(AND(G8>L8,G6>L6),"Fail > +2s",IF(AND(G8<J8,G7<J7),"Fail < -2s",IF(AND(G8<J8,G6<J6),"Fail < -2s","Pass")))) -> Fail > +2s | S8: =IF(E8="","",IF(G8>G7,"+",IF(G8<G7,"-",""))) -> + | X8: =AVERAGE(G6:G8) -> 26.943333 | AD8: =IF(H8="","",IF(H8>N8,"No","Yes")) -> Yes
B9: 4 | C9: 38308 | E9: 27.05 | F9: 27.11 | G9: =IF(AND(E9="",F9=""),NA(),AVERAGE(E9:F9)) -> 27.08 | H9: =IF(AND(E9="",F9=""),NA(),ABS(E9-F9)) -> 0.06 | I9: ='Plot Data'!$C$67 -> 23.433969 | J9: ='Plot Data'!$C$65 -> 23.539767 | K9: ='Plot Data'!$C$58 -> 23.751364 | L9: ='Plot Data'!$C$62 -> 23.96296 | M9: ='Plot Data'!$C$64 -> 24.068759 | N9: ='Plot Data'!$C$68 -> 0.12 | O9: =IF(G9>M9,">+3s",IF(G9<I9,"<-3s","Pass")) -> >+3s | P9: =IF(AND(G9>L9,G8>L8),"Fail > +2s",IF(AND(G9>L9,G7>L7),"Fail > +2s",IF(AND(G9<J9,G8<J8),"Fail < -2s",IF(AND(G9<J9,G7<J7),"Fail < -2s","Pass")))) -> Fail > +2s | S9: =IF(E9="","",IF(G9>G8,"+",IF(G9<G8,"-",""))) -> + | X9: =AVERAGE(G7:G9) -> 26.953333 | Y9: =AVERAGE(G6:G9) -> 26.9775 | AD9: =IF(H9="","",IF(H9>N9,"No","Yes")) -> Yes
B10: 5 | C10: 38673 | E10: 26.99 | F10: 27.01 | G10: =IF(AND(E10="",F10=""),NA(),AVERAGE(E10:F10)) -> 27 | H10: =IF(AND(E10="",F10=""),NA(),ABS(E10-F10)) -> 0.02 | I10: ='Plot Data'!$C$67 -> 23.433969 | J10: ='Plot Data'!$C$65 -> 23.539767 | K10: ='Plot Data'!$C$58 -> 23.751364 | L10: ='Plot Data'!$C$62 -> 23.96296 | M10: ='Plot Data'!$C$64 -> 24.068759 | N10: ='Plot Data'!$C$68 -> 0.12 | O10: =IF(G10>M10,">+3s",IF(G10<I10,"<-3s","Pass")) -> >+3s | P10: =IF(AND(G10>L10,G9>L9),"Fail > +2s",IF(AND(G10>L10,G8>L8),"Fail > +2s",IF(AND(G10<J10,G9<J9),"Fail < -2s",IF(AND(G10<J10,G8<J8),"Fail < -2s","Pass")))) -> Fail > +2s | S10: =IF(E10="","",IF(G10>G9,"+",IF(G10<G9,"-",""))) -> - | X10: =AVERAGE(G8:G10) -> 27.015 | Y10: =AVERAGE(G7:G10) -> 26.965 | Z10: =AVERAGE(G6:G10) -> 26.982 | AD10: =IF(H10="","",IF(H10>N10,"No","Yes")) -> Yes
B11: 6 | C11: 39038 | E11: 27.08 | F11: 27.08 | G11: =IF(AND(E11="",F11=""),NA(),AVERAGE(E11:F11)) -> 27.08 | H11: =IF(AND(E11="",F11=""),NA(),ABS(E11-F11)) -> 0 | I11: ='Plot Data'!$C$67 -> 23.433969 | J11: ='Plot Data'!$C$65 -> 23.539767 | K11: ='Plot Data'!$C$58 -> 23.751364 | L11: ='Plot Data'!$C$62 -> 23.96296 | M11: ='Plot Data'!$C$64 -> 24.068759 | N11: ='Plot Data'!$C$68 -> 0.12 | O11: =IF(G11>M11,">+3s",IF(G11<I11,"<-3s","Pass")) -> >+3s | P11: =IF(AND(G11>L11,G10>L10),"Fail > +2s",IF(AND(G11>L11,G9>L9),"Fail > +2s",IF(AND(G11<J11,G10<J10),"Fail < -2s",IF(AND(G11<J11,G9<J9),"Fail < -2s","Pass")))) -> Fail > +2s | S11: =IF(E11="","",IF(G11>G10,"+",IF(G11<G10,"-",""))) -> + | X11: =AVERAGE(G9:G11) -> 27.053333 | Y11: =AVERAGE(G8:G11) -> 27.03125 | Z11: =AVERAGE(G7:G11) -> 26.988 | AA11: =AVERAGE(G6:G11) -> 26.998333 | AD11: =IF(H11="","",IF(H11>N11,"No","Yes")) -> Yes
B12: 7 | E12: 27.03 | F12: 27.03 | G12: =IF(AND(E12="",F12=""),NA(),AVERAGE(E12:F12)) -> 27.03 | H12: =IF(AND(E12="",F12=""),NA(),ABS(E12-F12)) -> 0 | I12: ='Plot Data'!$C$67 -> 23.433969 | J12: ='Plot Data'!$C$65 -> 23.539767 | K12: ='Plot Data'!$C$58 -> 23.751364 | L12: ='Plot Data'!$C$62 -> 23.96296 | M12: ='Plot Data'!$C$64 -> 24.068759 | N12: ='Plot Data'!$C$68 -> 0.12 | O12: =IF(G12>M12,">+3s",IF(G12<I12,"<-3s","Pass")) -> >+3s | P12: =IF(AND(G12>L12,G11>L11),"Fail > +2s",IF(AND(G12>L12,G10>L10),"Fail > +2s",IF(AND(G12<J12,G11<J11),"Fail < -2s",IF(AND(G12<J12,G10<J10),"Fail < -2s","Pass")))) -> Fail > +2s | R12: =IF(AND(G12>G11,G11>G10,G10>G9,G9>G8,G8>G7,G7>G6),"Fail +ve trend",IF(AND(G12<G11,G11<G10,G10<G9,G9<G8,G8<G7,G7<G6),"Fail -ve trend","Pass")) -> Pass | S12: =IF(E12="","",IF(G12>G11,"+",IF(G12<G11,"-",""))) -> - | X12: =AVERAGE(G10:G12) -> 27.036667 | Y12: =AVERAGE(G9:G12) -> 27.0475 | Z12: =AVERAGE(G8:G12) -> 27.031 | AA12: =AVERAGE(G7:G12) -> 26.995 | AD12: =IF(H12="","",IF(H12>N12,"No","Yes")) -> Yes
B13: 8 | E13: 27.1 | F13: 27.1 | G13: =IF(AND(E13="",F13=""),NA(),AVERAGE(E13:F13)) -> 27.1 | H13: =IF(AND(E13="",F13=""),NA(),ABS(E13-F13)) -> 0 | I13: ='Plot Data'!$C$67 -> 23.433969 | J13: ='Plot Data'!$C$65 -> 23.539767 | K13: ='Plot Data'!$C$58 -> 23.751364 | L13: ='Plot Data'!$C$62 -> 23.96296 | M13: ='Plot Data'!$C$64 -> 24.068759 | N13: ='Plot Data'!$C$68 -> 0.12 | O13: =IF(G13>M13,">+3s",IF(G13<I13,"<-3s","Pass")) -> >+3s | P13: =IF(AND(G13>L13,G12>L12),"Fail > +2s",IF(AND(G13>L13,G11>L11),"Fail > +2s",IF(AND(G13<J13,G12<J12),"Fail < -2s",IF(AND(G13<J13,G11<J11),"Fail < -2s","Pass")))) -> Fail > +2s | Q13: =IF(AND(G13>K13,G12>K13,G11>K13,G10>K13,G9>K13,G8>K13,G7>K13,G6>K13),"Fail +ve bias",IF(AND(G13<K13,G12<K13,G11<K13,G10<K13,G9<K13,G8<K13,G7<K13,G6<K13),"Fail -ve bias","Pass")) -> Fail +ve bias | R13: =IF(AND(G13>G12,G12>G11,G11>G10,G10>G9,G9>G8,G8>G7),"Fail +ve trend",IF(AND(G13<G12,G12<G11,G11<G10,G10<G9,G9<G8,G8<G7),"Fail -ve trend","Pass")) -> Pass | S13: =IF(E13="","",IF(G13>G12,"+",IF(G13<G12,"-",""))) -> + | X13: =AVERAGE(G11:G13) -> 27.07 | Y13: =AVERAGE(G10:G13) -> 27.0525 | Z13: =AVERAGE(G9:G13) -> 27.058 | AA13: =AVERAGE(G8:G13) -> 27.0425 | AD13: =IF(H13="","",IF(H13>N13,"No","Yes")) -> Yes
B14: 9 | E14: 27.06 | F14: 27.06 | G14: =IF(AND(E14="",F14=""),NA(),AVERAGE(E14:F14)) -> 27.06 | H14: =IF(AND(E14="",F14=""),NA(),ABS(E14-F14)) -> 0 | I14: ='Plot Data'!$C$67 -> 23.433969 | J14: ='Plot Data'!$C$65 -> 23.539767 | K14: ='Plot Data'!$C$58 -> 23.751364 | L14: ='Plot Data'!$C$62 -> 23.96296 | M14: ='Plot Data'!$C$64 -> 24.068759 | N14: ='Plot Data'!$C$68 -> 0.12 | O14: =IF(G14>M14,">+3s",IF(G14<I14,"<-3s","Pass")) -> >+3s | P14: =IF(AND(G14>L14,G13>L13),"Fail > +2s",IF(AND(G14>L14,G12>L12),"Fail > +2s",IF(AND(G14<J14,G13<J13),"Fail < -2s",IF(AND(G14<J14,G12<J12),"Fail < -2s","Pass")))) -> Fail > +2s | Q14: =IF(AND(G14>K14,G13>K14,G12>K14,G11>K14,G10>K14,G9>K14,G8>K14,G7>K14),"Fail +ve bias",IF(AND(G14<K14,G13<K14,G12<K14,G11<K14,G10<K14,G9<K14,G8<K14,G7<K14),"Fail -ve bias","Pass")) -> Fail +ve bias | R14: =IF(AND(G14>G13,G13>G12,G12>G11,G11>G10,G10>G9,G9>G8),"Fail +ve trend",IF(AND(G14<G13,G13<G12,G12<G11,G11<G10,G10<G9,G9<G8),"Fail -ve trend","Pass")) -> Pass | S14: =IF(E14="","",IF(G14>G13,"+",IF(G14<G13,"-",""))) -> - | X14: =AVERAGE(G12:G14) -> 27.063333 | Y14: =AVERAGE(G11:G14) -> 27.0675 | Z14: =AVERAGE(G10:G14) -> 27.054 | AA14: =AVERAGE(G9:G14) -> 27.058333 | AD14: =IF(H14="","",IF(H14>N14,"No","Yes")) -> Yes
